INFO:werkzeug: * Running on http://127.0.0.1:5000 (Press CTRL+C to quit)
 * Running on http://127.0.0.1:5000 (Press CTRL+C to quit)
INFO:root:Запрос
Запрос
INFO:werkzeug:127.0.0.1 - - [15/Jul/2022 03:34:16] "GET /api/posts/2 HTTP/1.1" 200 -
127.0.0.1 - - [15/Jul/2022 03:34:16] "GET /api/posts/2 HTTP/1.1" 200 -
INFO:root:Запрос
Запрос
INFO:werkzeug:127.0.0.1 - - [15/Jul/2022 03:34:29] "GET /api/posts/1 HTTP/1.1" 200 -
127.0.0.1 - - [15/Jul/2022 03:34:29] "GET /api/posts/1 HTTP/1.1" 200 -
INFO:root:Запрос
Запрос
INFO:werkzeug:127.0.0.1 - - [15/Jul/2022 03:34:35] "GET /api/posts/0 HTTP/1.1" 200 -
127.0.0.1 - - [15/Jul/2022 03:34:35] "GET /api/posts/0 HTTP/1.1" 200 -
INFO:root:Запрос
Запрос
INFO:werkzeug:127.0.0.1 - - [15/Jul/2022 03:34:42] "GET /api/posts/6 HTTP/1.1" 200 -
127.0.0.1 - - [15/Jul/2022 03:34:42] "GET /api/posts/6 HTTP/1.1" 200 -
INFO:werkzeug: * Running on http://127.0.0.1:5000 (Press CTRL+C to quit)
 * Running on http://127.0.0.1:5000 (Press CTRL+C to quit)
INFO:root:Запрос
Запрос
INFO:werkzeug:127.0.0.1 - - [15/Jul/2022 03:37:12] "GET /api/posts/6 HTTP/1.1" 200 -
127.0.0.1 - - [15/Jul/2022 03:37:12] "GET /api/posts/6 HTTP/1.1" 200 -
INFO:root:Запрос
Запрос
INFO:werkzeug:127.0.0.1 - - [15/Jul/2022 03:38:46] "GET /api/posts/6 HTTP/1.1" 200 -
127.0.0.1 - - [15/Jul/2022 03:38:46] "GET /api/posts/6 HTTP/1.1" 200 -
INFO:werkzeug: * Running on http://127.0.0.1:5000 (Press CTRL+C to quit)
 * Running on http://127.0.0.1:5000 (Press CTRL+C to quit)
INFO:root:Запрос всех книг
Запрос всех книг
INFO:werkzeug:127.0.0.1 - - [15/Jul/2022 03:38:57] "GET /api/posts/6 HTTP/1.1" 200 -
127.0.0.1 - - [15/Jul/2022 03:38:57] "GET /api/posts/6 HTTP/1.1" 200 -
INFO:werkzeug: * Running on http://127.0.0.1:5000 (Press CTRL+C to quit)
 * Running on http://127.0.0.1:5000 (Press CTRL+C to quit)
INFO:root:Запрос всех книг
Запрос всех книг
INFO:root:Запрос всех книг
Запрос всех книг
INFO:werkzeug:127.0.0.1 - - [15/Jul/2022 03:39:53] "GET /api/posts/6 HTTP/1.1" 200 -
127.0.0.1 - - [15/Jul/2022 03:39:53] "GET /api/posts/6 HTTP/1.1" 200 -
INFO:werkzeug: * Running on http://127.0.0.1:5000 (Press CTRL+C to quit)
 * Running on http://127.0.0.1:5000 (Press CTRL+C to quit)
INFO:root:Запрос всех книг
Запрос всех книг
INFO:root:Запрос всех книг
Запрос всех книг
INFO:werkzeug:127.0.0.1 - - [15/Jul/2022 09:29:42] "GET /api/posts/6 HTTP/1.1" 200 -
127.0.0.1 - - [15/Jul/2022 09:29:42] "GET /api/posts/6 HTTP/1.1" 200 -
INFO:werkzeug: * Running on http://127.0.0.1:5000 (Press CTRL+C to quit)
 * Running on http://127.0.0.1:5000 (Press CTRL+C to quit)
INFO:werkzeug: * Running on http://127.0.0.1:5000 (Press CTRL+C to quit)
 * Running on http://127.0.0.1:5000 (Press CTRL+C to quit)
INFO:werkzeug: * Running on http://127.0.0.1:5000 (Press CTRL+C to quit)
 * Running on http://127.0.0.1:5000 (Press CTRL+C to quit)
INFO:werkzeug:127.0.0.1 - - [17/Jul/2022 11:37:32] "GET / HTTP/1.1" 200 -
127.0.0.1 - - [17/Jul/2022 11:37:32] "GET / HTTP/1.1" 200 -
INFO:werkzeug:127.0.0.1 - - [17/Jul/2022 11:37:32] "GET /static/styles.min.css HTTP/1.1" 200 -
127.0.0.1 - - [17/Jul/2022 11:37:32] "GET /static/styles.min.css HTTP/1.1" 200 -
INFO:werkzeug:127.0.0.1 - - [17/Jul/2022 11:37:32] "[33mGET /favicon.ico HTTP/1.1[0m" 404 -
127.0.0.1 - - [17/Jul/2022 11:37:32] "[33mGET /favicon.ico HTTP/1.1[0m" 404 -
INFO:werkzeug:127.0.0.1 - - [17/Jul/2022 11:37:34] "GET /search HTTP/1.1" 200 -
127.0.0.1 - - [17/Jul/2022 11:37:34] "GET /search HTTP/1.1" 200 -
INFO:werkzeug:127.0.0.1 - - [17/Jul/2022 11:37:34] "[36mGET /static/styles.min.css HTTP/1.1[0m" 304 -
127.0.0.1 - - [17/Jul/2022 11:37:34] "[36mGET /static/styles.min.css HTTP/1.1[0m" 304 -
INFO:werkzeug:127.0.0.1 - - [17/Jul/2022 11:37:35] "GET / HTTP/1.1" 200 -
127.0.0.1 - - [17/Jul/2022 11:37:35] "GET / HTTP/1.1" 200 -
INFO:werkzeug:127.0.0.1 - - [17/Jul/2022 11:37:35] "[36mGET /static/styles.min.css HTTP/1.1[0m" 304 -
127.0.0.1 - - [17/Jul/2022 11:37:35] "[36mGET /static/styles.min.css HTTP/1.1[0m" 304 -
INFO:werkzeug:127.0.0.1 - - [17/Jul/2022 11:37:37] "GET /users/leo HTTP/1.1" 200 -
127.0.0.1 - - [17/Jul/2022 11:37:37] "GET /users/leo HTTP/1.1" 200 -
INFO:werkzeug:127.0.0.1 - - [17/Jul/2022 11:37:37] "[36mGET /static/styles.min.css HTTP/1.1[0m" 304 -
127.0.0.1 - - [17/Jul/2022 11:37:37] "[36mGET /static/styles.min.css HTTP/1.1[0m" 304 -
INFO:werkzeug: * Running on http://127.0.0.1:5000 (Press CTRL+C to quit)
 * Running on http://127.0.0.1:5000 (Press CTRL+C to quit)
ERROR:app.run:Exception on / [GET]
Traceback (most recent call last):
  File "C:\Users\Павел\PycharmProjects\homeCourse2\app\post\dao\post_dao.py", line 19, in load_data
    with open(self.path, "r", encoding="utf-8") as f:
FileNotFoundError: [Errno 2] No such file or directory: 'C:\\Users\\Павел\\data\\data.json'

During handling of the above exception, another exception occurred:

Traceback (most recent call last):
  File "C:\Users\Павел\PycharmProjects\homeCourse2\FLASK\lib\site-packages\flask\app.py", line 2077, in wsgi_app
    response = self.full_dispatch_request()
  File "C:\Users\Павел\PycharmProjects\homeCourse2\FLASK\lib\site-packages\flask\app.py", line 1525, in full_dispatch_request
    rv = self.handle_user_exception(e)
  File "C:\Users\Павел\PycharmProjects\homeCourse2\FLASK\lib\site-packages\flask\app.py", line 1523, in full_dispatch_request
    rv = self.dispatch_request()
  File "C:\Users\Павел\PycharmProjects\homeCourse2\FLASK\lib\site-packages\flask\app.py", line 1509, in dispatch_request
    return self.ensure_sync(self.view_functions[rule.endpoint])(**req.view_args)
  File "C:\Users\Павел\PycharmProjects\homeCourse2\app\main\views.py", line 9, in page_index
    post = posts.load_data()
  File "C:\Users\Павел\PycharmProjects\homeCourse2\app\post\dao\post_dao.py", line 22, in load_data
    raise DataSourceError(f"Не удается получить данные из файла{self.path}")
exceptions.data_exceptions.DataSourceError: Не удается получить данные из файлаC:\Users\Павел\data\data.json
Exception on / [GET]
Traceback (most recent call last):
  File "C:\Users\Павел\PycharmProjects\homeCourse2\app\post\dao\post_dao.py", line 19, in load_data
    with open(self.path, "r", encoding="utf-8") as f:
FileNotFoundError: [Errno 2] No such file or directory: 'C:\\Users\\Павел\\data\\data.json'

During handling of the above exception, another exception occurred:

Traceback (most recent call last):
  File "C:\Users\Павел\PycharmProjects\homeCourse2\FLASK\lib\site-packages\flask\app.py", line 2077, in wsgi_app
    response = self.full_dispatch_request()
  File "C:\Users\Павел\PycharmProjects\homeCourse2\FLASK\lib\site-packages\flask\app.py", line 1525, in full_dispatch_request
    rv = self.handle_user_exception(e)
  File "C:\Users\Павел\PycharmProjects\homeCourse2\FLASK\lib\site-packages\flask\app.py", line 1523, in full_dispatch_request
    rv = self.dispatch_request()
  File "C:\Users\Павел\PycharmProjects\homeCourse2\FLASK\lib\site-packages\flask\app.py", line 1509, in dispatch_request
    return self.ensure_sync(self.view_functions[rule.endpoint])(**req.view_args)
  File "C:\Users\Павел\PycharmProjects\homeCourse2\app\main\views.py", line 9, in page_index
    post = posts.load_data()
  File "C:\Users\Павел\PycharmProjects\homeCourse2\app\post\dao\post_dao.py", line 22, in load_data
    raise DataSourceError(f"Не удается получить данные из файла{self.path}")
exceptions.data_exceptions.DataSourceError: Не удается получить данные из файлаC:\Users\Павел\data\data.json
INFO:werkzeug:127.0.0.1 - - [17/Jul/2022 14:58:01] "[35m[1mGET / HTTP/1.1[0m" 500 -
127.0.0.1 - - [17/Jul/2022 14:58:01] "[35m[1mGET / HTTP/1.1[0m" 500 -
INFO:werkzeug: * Running on http://127.0.0.1:5000 (Press CTRL+C to quit)
 * Running on http://127.0.0.1:5000 (Press CTRL+C to quit)
ERROR:app.run:Exception on / [GET]
Traceback (most recent call last):
  File "C:\Users\Павел\PycharmProjects\homeCourse2\app\post\dao\post_dao.py", line 19, in load_data
    with open(self.path, "r", encoding="utf-8") as f:
FileNotFoundError: [Errno 2] No such file or directory: 'C:\\Users\\Павел\\data\\data.json'

During handling of the above exception, another exception occurred:

Traceback (most recent call last):
  File "C:\Users\Павел\PycharmProjects\homeCourse2\FLASK\lib\site-packages\flask\app.py", line 2077, in wsgi_app
    response = self.full_dispatch_request()
  File "C:\Users\Павел\PycharmProjects\homeCourse2\FLASK\lib\site-packages\flask\app.py", line 1525, in full_dispatch_request
    rv = self.handle_user_exception(e)
  File "C:\Users\Павел\PycharmProjects\homeCourse2\FLASK\lib\site-packages\flask\app.py", line 1523, in full_dispatch_request
    rv = self.dispatch_request()
  File "C:\Users\Павел\PycharmProjects\homeCourse2\FLASK\lib\site-packages\flask\app.py", line 1509, in dispatch_request
    return self.ensure_sync(self.view_functions[rule.endpoint])(**req.view_args)
  File "C:\Users\Павел\PycharmProjects\homeCourse2\app\main\views.py", line 9, in page_index
    post = posts.load_data()
  File "C:\Users\Павел\PycharmProjects\homeCourse2\app\post\dao\post_dao.py", line 22, in load_data
    raise DataSourceError(f"Не удается получить данные из файла{self.path}")
exceptions.data_exceptions.DataSourceError: Не удается получить данные из файлаC:\Users\Павел\data\data.json
Exception on / [GET]
Traceback (most recent call last):
  File "C:\Users\Павел\PycharmProjects\homeCourse2\app\post\dao\post_dao.py", line 19, in load_data
    with open(self.path, "r", encoding="utf-8") as f:
FileNotFoundError: [Errno 2] No such file or directory: 'C:\\Users\\Павел\\data\\data.json'

During handling of the above exception, another exception occurred:

Traceback (most recent call last):
  File "C:\Users\Павел\PycharmProjects\homeCourse2\FLASK\lib\site-packages\flask\app.py", line 2077, in wsgi_app
    response = self.full_dispatch_request()
  File "C:\Users\Павел\PycharmProjects\homeCourse2\FLASK\lib\site-packages\flask\app.py", line 1525, in full_dispatch_request
    rv = self.handle_user_exception(e)
  File "C:\Users\Павел\PycharmProjects\homeCourse2\FLASK\lib\site-packages\flask\app.py", line 1523, in full_dispatch_request
    rv = self.dispatch_request()
  File "C:\Users\Павел\PycharmProjects\homeCourse2\FLASK\lib\site-packages\flask\app.py", line 1509, in dispatch_request
    return self.ensure_sync(self.view_functions[rule.endpoint])(**req.view_args)
  File "C:\Users\Павел\PycharmProjects\homeCourse2\app\main\views.py", line 9, in page_index
    post = posts.load_data()
  File "C:\Users\Павел\PycharmProjects\homeCourse2\app\post\dao\post_dao.py", line 22, in load_data
    raise DataSourceError(f"Не удается получить данные из файла{self.path}")
exceptions.data_exceptions.DataSourceError: Не удается получить данные из файлаC:\Users\Павел\data\data.json
INFO:werkzeug:127.0.0.1 - - [17/Jul/2022 14:58:18] "[35m[1mGET / HTTP/1.1[0m" 500 -
127.0.0.1 - - [17/Jul/2022 14:58:18] "[35m[1mGET / HTTP/1.1[0m" 500 -
ERROR:app.run:Exception on / [GET]
Traceback (most recent call last):
  File "C:\Users\Павел\PycharmProjects\homeCourse2\app\post\dao\post_dao.py", line 19, in load_data
    with open(self.path, "r", encoding="utf-8") as f:
FileNotFoundError: [Errno 2] No such file or directory: 'C:\\Users\\Павел\\data\\data.json'

During handling of the above exception, another exception occurred:

Traceback (most recent call last):
  File "C:\Users\Павел\PycharmProjects\homeCourse2\FLASK\lib\site-packages\flask\app.py", line 2077, in wsgi_app
    response = self.full_dispatch_request()
  File "C:\Users\Павел\PycharmProjects\homeCourse2\FLASK\lib\site-packages\flask\app.py", line 1525, in full_dispatch_request
    rv = self.handle_user_exception(e)
  File "C:\Users\Павел\PycharmProjects\homeCourse2\FLASK\lib\site-packages\flask\app.py", line 1523, in full_dispatch_request
    rv = self.dispatch_request()
  File "C:\Users\Павел\PycharmProjects\homeCourse2\FLASK\lib\site-packages\flask\app.py", line 1509, in dispatch_request
    return self.ensure_sync(self.view_functions[rule.endpoint])(**req.view_args)
  File "C:\Users\Павел\PycharmProjects\homeCourse2\app\main\views.py", line 9, in page_index
    post = posts.load_data()
  File "C:\Users\Павел\PycharmProjects\homeCourse2\app\post\dao\post_dao.py", line 22, in load_data
    raise DataSourceError(f"Не удается получить данные из файла{self.path}")
exceptions.data_exceptions.DataSourceError: Не удается получить данные из файлаC:\Users\Павел\data\data.json
Exception on / [GET]
Traceback (most recent call last):
  File "C:\Users\Павел\PycharmProjects\homeCourse2\app\post\dao\post_dao.py", line 19, in load_data
    with open(self.path, "r", encoding="utf-8") as f:
FileNotFoundError: [Errno 2] No such file or directory: 'C:\\Users\\Павел\\data\\data.json'

During handling of the above exception, another exception occurred:

Traceback (most recent call last):
  File "C:\Users\Павел\PycharmProjects\homeCourse2\FLASK\lib\site-packages\flask\app.py", line 2077, in wsgi_app
    response = self.full_dispatch_request()
  File "C:\Users\Павел\PycharmProjects\homeCourse2\FLASK\lib\site-packages\flask\app.py", line 1525, in full_dispatch_request
    rv = self.handle_user_exception(e)
  File "C:\Users\Павел\PycharmProjects\homeCourse2\FLASK\lib\site-packages\flask\app.py", line 1523, in full_dispatch_request
    rv = self.dispatch_request()
  File "C:\Users\Павел\PycharmProjects\homeCourse2\FLASK\lib\site-packages\flask\app.py", line 1509, in dispatch_request
    return self.ensure_sync(self.view_functions[rule.endpoint])(**req.view_args)
  File "C:\Users\Павел\PycharmProjects\homeCourse2\app\main\views.py", line 9, in page_index
    post = posts.load_data()
  File "C:\Users\Павел\PycharmProjects\homeCourse2\app\post\dao\post_dao.py", line 22, in load_data
    raise DataSourceError(f"Не удается получить данные из файла{self.path}")
exceptions.data_exceptions.DataSourceError: Не удается получить данные из файлаC:\Users\Павел\data\data.json
INFO:werkzeug:127.0.0.1 - - [17/Jul/2022 14:58:21] "[35m[1mGET / HTTP/1.1[0m" 500 -
127.0.0.1 - - [17/Jul/2022 14:58:21] "[35m[1mGET / HTTP/1.1[0m" 500 -
INFO:werkzeug: * Running on http://127.0.0.1:5000 (Press CTRL+C to quit)
 * Running on http://127.0.0.1:5000 (Press CTRL+C to quit)
ERROR:app.run:Exception on / [GET]
Traceback (most recent call last):
  File "C:\Users\Павел\PycharmProjects\homeCourse2\app\post\dao\post_dao.py", line 19, in load_data
    with open(self.path, "r", encoding="utf-8") as f:
FileNotFoundError: [Errno 2] No such file or directory: 'C:\\Users\\Павел\\app\\data\\data.json'

During handling of the above exception, another exception occurred:

Traceback (most recent call last):
  File "C:\Users\Павел\PycharmProjects\homeCourse2\FLASK\lib\site-packages\flask\app.py", line 2077, in wsgi_app
    response = self.full_dispatch_request()
  File "C:\Users\Павел\PycharmProjects\homeCourse2\FLASK\lib\site-packages\flask\app.py", line 1525, in full_dispatch_request
    rv = self.handle_user_exception(e)
  File "C:\Users\Павел\PycharmProjects\homeCourse2\FLASK\lib\site-packages\flask\app.py", line 1523, in full_dispatch_request
    rv = self.dispatch_request()
  File "C:\Users\Павел\PycharmProjects\homeCourse2\FLASK\lib\site-packages\flask\app.py", line 1509, in dispatch_request
    return self.ensure_sync(self.view_functions[rule.endpoint])(**req.view_args)
  File "C:\Users\Павел\PycharmProjects\homeCourse2\app\main\views.py", line 9, in page_index
    post = posts.load_data()
  File "C:\Users\Павел\PycharmProjects\homeCourse2\app\post\dao\post_dao.py", line 22, in load_data
    raise DataSourceError(f"Не удается получить данные из файла{self.path}")
exceptions.data_exceptions.DataSourceError: Не удается получить данные из файлаC:\Users\Павел\app\data\data.json
Exception on / [GET]
Traceback (most recent call last):
  File "C:\Users\Павел\PycharmProjects\homeCourse2\app\post\dao\post_dao.py", line 19, in load_data
    with open(self.path, "r", encoding="utf-8") as f:
FileNotFoundError: [Errno 2] No such file or directory: 'C:\\Users\\Павел\\app\\data\\data.json'

During handling of the above exception, another exception occurred:

Traceback (most recent call last):
  File "C:\Users\Павел\PycharmProjects\homeCourse2\FLASK\lib\site-packages\flask\app.py", line 2077, in wsgi_app
    response = self.full_dispatch_request()
  File "C:\Users\Павел\PycharmProjects\homeCourse2\FLASK\lib\site-packages\flask\app.py", line 1525, in full_dispatch_request
    rv = self.handle_user_exception(e)
  File "C:\Users\Павел\PycharmProjects\homeCourse2\FLASK\lib\site-packages\flask\app.py", line 1523, in full_dispatch_request
    rv = self.dispatch_request()
  File "C:\Users\Павел\PycharmProjects\homeCourse2\FLASK\lib\site-packages\flask\app.py", line 1509, in dispatch_request
    return self.ensure_sync(self.view_functions[rule.endpoint])(**req.view_args)
  File "C:\Users\Павел\PycharmProjects\homeCourse2\app\main\views.py", line 9, in page_index
    post = posts.load_data()
  File "C:\Users\Павел\PycharmProjects\homeCourse2\app\post\dao\post_dao.py", line 22, in load_data
    raise DataSourceError(f"Не удается получить данные из файла{self.path}")
exceptions.data_exceptions.DataSourceError: Не удается получить данные из файлаC:\Users\Павел\app\data\data.json
INFO:werkzeug:127.0.0.1 - - [17/Jul/2022 14:59:40] "[35m[1mGET / HTTP/1.1[0m" 500 -
127.0.0.1 - - [17/Jul/2022 14:59:40] "[35m[1mGET / HTTP/1.1[0m" 500 -
INFO:werkzeug: * Running on http://127.0.0.1:5000 (Press CTRL+C to quit)
 * Running on http://127.0.0.1:5000 (Press CTRL+C to quit)
ERROR:app.run:Exception on / [GET]
Traceback (most recent call last):
  File "C:\Users\Павел\PycharmProjects\homeCourse2\app\post\dao\post_dao.py", line 18, in load_data
    with open(self.path, "r", encoding="utf-8") as f:
FileNotFoundError: [Errno 2] No such file or directory: 'data\\data.json'

During handling of the above exception, another exception occurred:

Traceback (most recent call last):
  File "C:\Users\Павел\PycharmProjects\homeCourse2\FLASK\lib\site-packages\flask\app.py", line 2077, in wsgi_app
    response = self.full_dispatch_request()
  File "C:\Users\Павел\PycharmProjects\homeCourse2\FLASK\lib\site-packages\flask\app.py", line 1525, in full_dispatch_request
    rv = self.handle_user_exception(e)
  File "C:\Users\Павел\PycharmProjects\homeCourse2\FLASK\lib\site-packages\flask\app.py", line 1523, in full_dispatch_request
    rv = self.dispatch_request()
  File "C:\Users\Павел\PycharmProjects\homeCourse2\FLASK\lib\site-packages\flask\app.py", line 1509, in dispatch_request
    return self.ensure_sync(self.view_functions[rule.endpoint])(**req.view_args)
  File "C:\Users\Павел\PycharmProjects\homeCourse2\app\main\views.py", line 9, in page_index
    post = posts.load_data()
  File "C:\Users\Павел\PycharmProjects\homeCourse2\app\post\dao\post_dao.py", line 21, in load_data
    raise DataSourceError(f"Не удается получить данные из файла{self.path}")
exceptions.data_exceptions.DataSourceError: Не удается получить данные из файлаdata\data.json
Exception on / [GET]
Traceback (most recent call last):
  File "C:\Users\Павел\PycharmProjects\homeCourse2\app\post\dao\post_dao.py", line 18, in load_data
    with open(self.path, "r", encoding="utf-8") as f:
FileNotFoundError: [Errno 2] No such file or directory: 'data\\data.json'

During handling of the above exception, another exception occurred:

Traceback (most recent call last):
  File "C:\Users\Павел\PycharmProjects\homeCourse2\FLASK\lib\site-packages\flask\app.py", line 2077, in wsgi_app
    response = self.full_dispatch_request()
  File "C:\Users\Павел\PycharmProjects\homeCourse2\FLASK\lib\site-packages\flask\app.py", line 1525, in full_dispatch_request
    rv = self.handle_user_exception(e)
  File "C:\Users\Павел\PycharmProjects\homeCourse2\FLASK\lib\site-packages\flask\app.py", line 1523, in full_dispatch_request
    rv = self.dispatch_request()
  File "C:\Users\Павел\PycharmProjects\homeCourse2\FLASK\lib\site-packages\flask\app.py", line 1509, in dispatch_request
    return self.ensure_sync(self.view_functions[rule.endpoint])(**req.view_args)
  File "C:\Users\Павел\PycharmProjects\homeCourse2\app\main\views.py", line 9, in page_index
    post = posts.load_data()
  File "C:\Users\Павел\PycharmProjects\homeCourse2\app\post\dao\post_dao.py", line 21, in load_data
    raise DataSourceError(f"Не удается получить данные из файла{self.path}")
exceptions.data_exceptions.DataSourceError: Не удается получить данные из файлаdata\data.json
INFO:werkzeug:127.0.0.1 - - [17/Jul/2022 15:04:09] "[35m[1mGET / HTTP/1.1[0m" 500 -
127.0.0.1 - - [17/Jul/2022 15:04:09] "[35m[1mGET / HTTP/1.1[0m" 500 -
INFO:werkzeug: * Running on http://127.0.0.1:5000 (Press CTRL+C to quit)
 * Running on http://127.0.0.1:5000 (Press CTRL+C to quit)
ERROR:app.run:Exception on / [GET]
Traceback (most recent call last):
  File "C:\Users\Павел\PycharmProjects\homeCourse2\app\post\dao\post_dao.py", line 18, in load_data
    with open(self.path, "r", encoding="utf-8") as f:
FileNotFoundError: [Errno 2] No such file or directory: 'C:\\Users\\Павел\\PycharmProjects\\homeCourse2\\data.json'

During handling of the above exception, another exception occurred:

Traceback (most recent call last):
  File "C:\Users\Павел\PycharmProjects\homeCourse2\FLASK\lib\site-packages\flask\app.py", line 2077, in wsgi_app
    response = self.full_dispatch_request()
  File "C:\Users\Павел\PycharmProjects\homeCourse2\FLASK\lib\site-packages\flask\app.py", line 1525, in full_dispatch_request
    rv = self.handle_user_exception(e)
  File "C:\Users\Павел\PycharmProjects\homeCourse2\FLASK\lib\site-packages\flask\app.py", line 1523, in full_dispatch_request
    rv = self.dispatch_request()
  File "C:\Users\Павел\PycharmProjects\homeCourse2\FLASK\lib\site-packages\flask\app.py", line 1509, in dispatch_request
    return self.ensure_sync(self.view_functions[rule.endpoint])(**req.view_args)
  File "C:\Users\Павел\PycharmProjects\homeCourse2\app\main\views.py", line 9, in page_index
    post = posts.load_data()
  File "C:\Users\Павел\PycharmProjects\homeCourse2\app\post\dao\post_dao.py", line 21, in load_data
    raise DataSourceError(f"Не удается получить данные из файла{self.path}")
exceptions.data_exceptions.DataSourceError: Не удается получить данные из файлаC:\Users\Павел\PycharmProjects\homeCourse2\data.json
Exception on / [GET]
Traceback (most recent call last):
  File "C:\Users\Павел\PycharmProjects\homeCourse2\app\post\dao\post_dao.py", line 18, in load_data
    with open(self.path, "r", encoding="utf-8") as f:
FileNotFoundError: [Errno 2] No such file or directory: 'C:\\Users\\Павел\\PycharmProjects\\homeCourse2\\data.json'

During handling of the above exception, another exception occurred:

Traceback (most recent call last):
  File "C:\Users\Павел\PycharmProjects\homeCourse2\FLASK\lib\site-packages\flask\app.py", line 2077, in wsgi_app
    response = self.full_dispatch_request()
  File "C:\Users\Павел\PycharmProjects\homeCourse2\FLASK\lib\site-packages\flask\app.py", line 1525, in full_dispatch_request
    rv = self.handle_user_exception(e)
  File "C:\Users\Павел\PycharmProjects\homeCourse2\FLASK\lib\site-packages\flask\app.py", line 1523, in full_dispatch_request
    rv = self.dispatch_request()
  File "C:\Users\Павел\PycharmProjects\homeCourse2\FLASK\lib\site-packages\flask\app.py", line 1509, in dispatch_request
    return self.ensure_sync(self.view_functions[rule.endpoint])(**req.view_args)
  File "C:\Users\Павел\PycharmProjects\homeCourse2\app\main\views.py", line 9, in page_index
    post = posts.load_data()
  File "C:\Users\Павел\PycharmProjects\homeCourse2\app\post\dao\post_dao.py", line 21, in load_data
    raise DataSourceError(f"Не удается получить данные из файла{self.path}")
exceptions.data_exceptions.DataSourceError: Не удается получить данные из файлаC:\Users\Павел\PycharmProjects\homeCourse2\data.json
INFO:werkzeug:127.0.0.1 - - [17/Jul/2022 15:06:44] "[35m[1mGET / HTTP/1.1[0m" 500 -
127.0.0.1 - - [17/Jul/2022 15:06:44] "[35m[1mGET / HTTP/1.1[0m" 500 -
ERROR:app.run:Exception on / [GET]
Traceback (most recent call last):
  File "C:\Users\Павел\PycharmProjects\homeCourse2\app\post\dao\post_dao.py", line 18, in load_data
    with open(self.path, "r", encoding="utf-8") as f:
FileNotFoundError: [Errno 2] No such file or directory: 'C:\\Users\\Павел\\PycharmProjects\\homeCourse2\\data.json'

During handling of the above exception, another exception occurred:

Traceback (most recent call last):
  File "C:\Users\Павел\PycharmProjects\homeCourse2\FLASK\lib\site-packages\flask\app.py", line 2077, in wsgi_app
    response = self.full_dispatch_request()
  File "C:\Users\Павел\PycharmProjects\homeCourse2\FLASK\lib\site-packages\flask\app.py", line 1525, in full_dispatch_request
    rv = self.handle_user_exception(e)
  File "C:\Users\Павел\PycharmProjects\homeCourse2\FLASK\lib\site-packages\flask\app.py", line 1523, in full_dispatch_request
    rv = self.dispatch_request()
  File "C:\Users\Павел\PycharmProjects\homeCourse2\FLASK\lib\site-packages\flask\app.py", line 1509, in dispatch_request
    return self.ensure_sync(self.view_functions[rule.endpoint])(**req.view_args)
  File "C:\Users\Павел\PycharmProjects\homeCourse2\app\main\views.py", line 9, in page_index
    post = posts.load_data()
  File "C:\Users\Павел\PycharmProjects\homeCourse2\app\post\dao\post_dao.py", line 21, in load_data
    raise DataSourceError(f"Не удается получить данные из файла{self.path}")
exceptions.data_exceptions.DataSourceError: Не удается получить данные из файлаC:\Users\Павел\PycharmProjects\homeCourse2\data.json
Exception on / [GET]
Traceback (most recent call last):
  File "C:\Users\Павел\PycharmProjects\homeCourse2\app\post\dao\post_dao.py", line 18, in load_data
    with open(self.path, "r", encoding="utf-8") as f:
FileNotFoundError: [Errno 2] No such file or directory: 'C:\\Users\\Павел\\PycharmProjects\\homeCourse2\\data.json'

During handling of the above exception, another exception occurred:

Traceback (most recent call last):
  File "C:\Users\Павел\PycharmProjects\homeCourse2\FLASK\lib\site-packages\flask\app.py", line 2077, in wsgi_app
    response = self.full_dispatch_request()
  File "C:\Users\Павел\PycharmProjects\homeCourse2\FLASK\lib\site-packages\flask\app.py", line 1525, in full_dispatch_request
    rv = self.handle_user_exception(e)
  File "C:\Users\Павел\PycharmProjects\homeCourse2\FLASK\lib\site-packages\flask\app.py", line 1523, in full_dispatch_request
    rv = self.dispatch_request()
  File "C:\Users\Павел\PycharmProjects\homeCourse2\FLASK\lib\site-packages\flask\app.py", line 1509, in dispatch_request
    return self.ensure_sync(self.view_functions[rule.endpoint])(**req.view_args)
  File "C:\Users\Павел\PycharmProjects\homeCourse2\app\main\views.py", line 9, in page_index
    post = posts.load_data()
  File "C:\Users\Павел\PycharmProjects\homeCourse2\app\post\dao\post_dao.py", line 21, in load_data
    raise DataSourceError(f"Не удается получить данные из файла{self.path}")
exceptions.data_exceptions.DataSourceError: Не удается получить данные из файлаC:\Users\Павел\PycharmProjects\homeCourse2\data.json
INFO:werkzeug:127.0.0.1 - - [17/Jul/2022 15:06:46] "[35m[1mGET / HTTP/1.1[0m" 500 -
127.0.0.1 - - [17/Jul/2022 15:06:46] "[35m[1mGET / HTTP/1.1[0m" 500 -
INFO:werkzeug: * Running on http://127.0.0.1:5000 (Press CTRL+C to quit)
 * Running on http://127.0.0.1:5000 (Press CTRL+C to quit)
ERROR:app.run:Exception on / [GET]
Traceback (most recent call last):
  File "C:\Users\Павел\PycharmProjects\homeCourse2\app\post\dao\post_dao.py", line 18, in load_data
    with open(self.path, "r", encoding="utf-8") as f:
FileNotFoundError: [Errno 2] No such file or directory: 'data\\data.json'

During handling of the above exception, another exception occurred:

Traceback (most recent call last):
  File "C:\Users\Павел\PycharmProjects\homeCourse2\FLASK\lib\site-packages\flask\app.py", line 2077, in wsgi_app
    response = self.full_dispatch_request()
  File "C:\Users\Павел\PycharmProjects\homeCourse2\FLASK\lib\site-packages\flask\app.py", line 1525, in full_dispatch_request
    rv = self.handle_user_exception(e)
  File "C:\Users\Павел\PycharmProjects\homeCourse2\FLASK\lib\site-packages\flask\app.py", line 1523, in full_dispatch_request
    rv = self.dispatch_request()
  File "C:\Users\Павел\PycharmProjects\homeCourse2\FLASK\lib\site-packages\flask\app.py", line 1509, in dispatch_request
    return self.ensure_sync(self.view_functions[rule.endpoint])(**req.view_args)
  File "C:\Users\Павел\PycharmProjects\homeCourse2\app\main\views.py", line 9, in page_index
    post = posts.load_data()
  File "C:\Users\Павел\PycharmProjects\homeCourse2\app\post\dao\post_dao.py", line 21, in load_data
    raise DataSourceError(f"Не удается получить данные из файла{self.path}")
exceptions.data_exceptions.DataSourceError: Не удается получить данные из файлаdata\data.json
Exception on / [GET]
Traceback (most recent call last):
  File "C:\Users\Павел\PycharmProjects\homeCourse2\app\post\dao\post_dao.py", line 18, in load_data
    with open(self.path, "r", encoding="utf-8") as f:
FileNotFoundError: [Errno 2] No such file or directory: 'data\\data.json'

During handling of the above exception, another exception occurred:

Traceback (most recent call last):
  File "C:\Users\Павел\PycharmProjects\homeCourse2\FLASK\lib\site-packages\flask\app.py", line 2077, in wsgi_app
    response = self.full_dispatch_request()
  File "C:\Users\Павел\PycharmProjects\homeCourse2\FLASK\lib\site-packages\flask\app.py", line 1525, in full_dispatch_request
    rv = self.handle_user_exception(e)
  File "C:\Users\Павел\PycharmProjects\homeCourse2\FLASK\lib\site-packages\flask\app.py", line 1523, in full_dispatch_request
    rv = self.dispatch_request()
  File "C:\Users\Павел\PycharmProjects\homeCourse2\FLASK\lib\site-packages\flask\app.py", line 1509, in dispatch_request
    return self.ensure_sync(self.view_functions[rule.endpoint])(**req.view_args)
  File "C:\Users\Павел\PycharmProjects\homeCourse2\app\main\views.py", line 9, in page_index
    post = posts.load_data()
  File "C:\Users\Павел\PycharmProjects\homeCourse2\app\post\dao\post_dao.py", line 21, in load_data
    raise DataSourceError(f"Не удается получить данные из файла{self.path}")
exceptions.data_exceptions.DataSourceError: Не удается получить данные из файлаdata\data.json
INFO:werkzeug:127.0.0.1 - - [17/Jul/2022 15:08:19] "[35m[1mGET / HTTP/1.1[0m" 500 -
127.0.0.1 - - [17/Jul/2022 15:08:19] "[35m[1mGET / HTTP/1.1[0m" 500 -
INFO:werkzeug: * Running on http://127.0.0.1:5000 (Press CTRL+C to quit)
 * Running on http://127.0.0.1:5000 (Press CTRL+C to quit)
ERROR:app.run:Exception on / [GET]
Traceback (most recent call last):
  File "C:\Users\Павел\PycharmProjects\homeCourse2\app\post\dao\post_dao.py", line 18, in load_data
    with open(self.path, "r", encoding="utf-8") as f:
FileNotFoundError: [Errno 2] No such file or directory: '/data.json'

During handling of the above exception, another exception occurred:

Traceback (most recent call last):
  File "C:\Users\Павел\PycharmProjects\homeCourse2\FLASK\lib\site-packages\flask\app.py", line 2077, in wsgi_app
    response = self.full_dispatch_request()
  File "C:\Users\Павел\PycharmProjects\homeCourse2\FLASK\lib\site-packages\flask\app.py", line 1525, in full_dispatch_request
    rv = self.handle_user_exception(e)
  File "C:\Users\Павел\PycharmProjects\homeCourse2\FLASK\lib\site-packages\flask\app.py", line 1523, in full_dispatch_request
    rv = self.dispatch_request()
  File "C:\Users\Павел\PycharmProjects\homeCourse2\FLASK\lib\site-packages\flask\app.py", line 1509, in dispatch_request
    return self.ensure_sync(self.view_functions[rule.endpoint])(**req.view_args)
  File "C:\Users\Павел\PycharmProjects\homeCourse2\app\main\views.py", line 9, in page_index
    post = posts.load_data()
  File "C:\Users\Павел\PycharmProjects\homeCourse2\app\post\dao\post_dao.py", line 21, in load_data
    raise DataSourceError(f"Не удается получить данные из файла{self.path}")
exceptions.data_exceptions.DataSourceError: Не удается получить данные из файла/data.json
Exception on / [GET]
Traceback (most recent call last):
  File "C:\Users\Павел\PycharmProjects\homeCourse2\app\post\dao\post_dao.py", line 18, in load_data
    with open(self.path, "r", encoding="utf-8") as f:
FileNotFoundError: [Errno 2] No such file or directory: '/data.json'

During handling of the above exception, another exception occurred:

Traceback (most recent call last):
  File "C:\Users\Павел\PycharmProjects\homeCourse2\FLASK\lib\site-packages\flask\app.py", line 2077, in wsgi_app
    response = self.full_dispatch_request()
  File "C:\Users\Павел\PycharmProjects\homeCourse2\FLASK\lib\site-packages\flask\app.py", line 1525, in full_dispatch_request
    rv = self.handle_user_exception(e)
  File "C:\Users\Павел\PycharmProjects\homeCourse2\FLASK\lib\site-packages\flask\app.py", line 1523, in full_dispatch_request
    rv = self.dispatch_request()
  File "C:\Users\Павел\PycharmProjects\homeCourse2\FLASK\lib\site-packages\flask\app.py", line 1509, in dispatch_request
    return self.ensure_sync(self.view_functions[rule.endpoint])(**req.view_args)
  File "C:\Users\Павел\PycharmProjects\homeCourse2\app\main\views.py", line 9, in page_index
    post = posts.load_data()
  File "C:\Users\Павел\PycharmProjects\homeCourse2\app\post\dao\post_dao.py", line 21, in load_data
    raise DataSourceError(f"Не удается получить данные из файла{self.path}")
exceptions.data_exceptions.DataSourceError: Не удается получить данные из файла/data.json
INFO:werkzeug:127.0.0.1 - - [17/Jul/2022 15:10:31] "[35m[1mGET / HTTP/1.1[0m" 500 -
127.0.0.1 - - [17/Jul/2022 15:10:31] "[35m[1mGET / HTTP/1.1[0m" 500 -
INFO:werkzeug: * Running on http://127.0.0.1:5000 (Press CTRL+C to quit)
 * Running on http://127.0.0.1:5000 (Press CTRL+C to quit)
ERROR:app.run:Exception on / [GET]
Traceback (most recent call last):
  File "C:\Users\Павел\PycharmProjects\homeCourse2\app\post\dao\post_dao.py", line 18, in load_data
    with open(self.path, "r", encoding="utf-8") as f:
FileNotFoundError: [Errno 2] No such file or directory: '/data.json'

During handling of the above exception, another exception occurred:

Traceback (most recent call last):
  File "C:\Users\Павел\PycharmProjects\homeCourse2\FLASK\lib\site-packages\flask\app.py", line 2077, in wsgi_app
    response = self.full_dispatch_request()
  File "C:\Users\Павел\PycharmProjects\homeCourse2\FLASK\lib\site-packages\flask\app.py", line 1525, in full_dispatch_request
    rv = self.handle_user_exception(e)
  File "C:\Users\Павел\PycharmProjects\homeCourse2\FLASK\lib\site-packages\flask\app.py", line 1523, in full_dispatch_request
    rv = self.dispatch_request()
  File "C:\Users\Павел\PycharmProjects\homeCourse2\FLASK\lib\site-packages\flask\app.py", line 1509, in dispatch_request
    return self.ensure_sync(self.view_functions[rule.endpoint])(**req.view_args)
  File "C:\Users\Павел\PycharmProjects\homeCourse2\app\main\views.py", line 9, in page_index
    post = posts.load_data()
  File "C:\Users\Павел\PycharmProjects\homeCourse2\app\post\dao\post_dao.py", line 21, in load_data
    raise DataSourceError(f"Не удается получить данные из файла{self.path}")
exceptions.data_exceptions.DataSourceError: Не удается получить данные из файла/data.json
Exception on / [GET]
Traceback (most recent call last):
  File "C:\Users\Павел\PycharmProjects\homeCourse2\app\post\dao\post_dao.py", line 18, in load_data
    with open(self.path, "r", encoding="utf-8") as f:
FileNotFoundError: [Errno 2] No such file or directory: '/data.json'

During handling of the above exception, another exception occurred:

Traceback (most recent call last):
  File "C:\Users\Павел\PycharmProjects\homeCourse2\FLASK\lib\site-packages\flask\app.py", line 2077, in wsgi_app
    response = self.full_dispatch_request()
  File "C:\Users\Павел\PycharmProjects\homeCourse2\FLASK\lib\site-packages\flask\app.py", line 1525, in full_dispatch_request
    rv = self.handle_user_exception(e)
  File "C:\Users\Павел\PycharmProjects\homeCourse2\FLASK\lib\site-packages\flask\app.py", line 1523, in full_dispatch_request
    rv = self.dispatch_request()
  File "C:\Users\Павел\PycharmProjects\homeCourse2\FLASK\lib\site-packages\flask\app.py", line 1509, in dispatch_request
    return self.ensure_sync(self.view_functions[rule.endpoint])(**req.view_args)
  File "C:\Users\Павел\PycharmProjects\homeCourse2\app\main\views.py", line 9, in page_index
    post = posts.load_data()
  File "C:\Users\Павел\PycharmProjects\homeCourse2\app\post\dao\post_dao.py", line 21, in load_data
    raise DataSourceError(f"Не удается получить данные из файла{self.path}")
exceptions.data_exceptions.DataSourceError: Не удается получить данные из файла/data.json
INFO:werkzeug:127.0.0.1 - - [17/Jul/2022 15:10:42] "[35m[1mGET / HTTP/1.1[0m" 500 -
127.0.0.1 - - [17/Jul/2022 15:10:42] "[35m[1mGET / HTTP/1.1[0m" 500 -
INFO:werkzeug: * Running on http://127.0.0.1:5000 (Press CTRL+C to quit)
 * Running on http://127.0.0.1:5000 (Press CTRL+C to quit)
INFO:werkzeug:127.0.0.1 - - [17/Jul/2022 15:11:18] "GET / HTTP/1.1" 200 -
127.0.0.1 - - [17/Jul/2022 15:11:18] "GET / HTTP/1.1" 200 -
INFO:werkzeug:127.0.0.1 - - [17/Jul/2022 15:11:22] "GET / HTTP/1.1" 200 -
127.0.0.1 - - [17/Jul/2022 15:11:22] "GET / HTTP/1.1" 200 -
INFO:werkzeug:127.0.0.1 - - [17/Jul/2022 15:11:36] "[36mGET /static/styles.min.css HTTP/1.1[0m" 304 -
127.0.0.1 - - [17/Jul/2022 15:11:36] "[36mGET /static/styles.min.css HTTP/1.1[0m" 304 -
INFO:werkzeug:127.0.0.1 - - [17/Jul/2022 15:11:36] "[33mGET /favicon.ico HTTP/1.1[0m" 404 -
127.0.0.1 - - [17/Jul/2022 15:11:36] "[33mGET /favicon.ico HTTP/1.1[0m" 404 -
INFO:werkzeug:127.0.0.1 - - [17/Jul/2022 15:11:38] "GET / HTTP/1.1" 200 -
127.0.0.1 - - [17/Jul/2022 15:11:38] "GET / HTTP/1.1" 200 -
INFO:werkzeug:127.0.0.1 - - [17/Jul/2022 15:11:39] "[36mGET /static/styles.min.css HTTP/1.1[0m" 304 -
127.0.0.1 - - [17/Jul/2022 15:11:39] "[36mGET /static/styles.min.css HTTP/1.1[0m" 304 -
INFO:werkzeug:127.0.0.1 - - [17/Jul/2022 15:11:41] "GET /search HTTP/1.1" 200 -
127.0.0.1 - - [17/Jul/2022 15:11:41] "GET /search HTTP/1.1" 200 -
INFO:werkzeug:127.0.0.1 - - [17/Jul/2022 15:11:41] "[36mGET /static/styles.min.css HTTP/1.1[0m" 304 -
127.0.0.1 - - [17/Jul/2022 15:11:41] "[36mGET /static/styles.min.css HTTP/1.1[0m" 304 -
INFO:werkzeug:127.0.0.1 - - [17/Jul/2022 15:11:42] "GET / HTTP/1.1" 200 -
127.0.0.1 - - [17/Jul/2022 15:11:42] "GET / HTTP/1.1" 200 -
INFO:werkzeug:127.0.0.1 - - [17/Jul/2022 15:11:42] "[36mGET /static/styles.min.css HTTP/1.1[0m" 304 -
127.0.0.1 - - [17/Jul/2022 15:11:42] "[36mGET /static/styles.min.css HTTP/1.1[0m" 304 -
INFO:werkzeug:127.0.0.1 - - [17/Jul/2022 15:11:44] "GET /search HTTP/1.1" 200 -
127.0.0.1 - - [17/Jul/2022 15:11:44] "GET /search HTTP/1.1" 200 -
INFO:werkzeug:127.0.0.1 - - [17/Jul/2022 15:11:45] "[36mGET /static/styles.min.css HTTP/1.1[0m" 304 -
127.0.0.1 - - [17/Jul/2022 15:11:45] "[36mGET /static/styles.min.css HTTP/1.1[0m" 304 -
INFO:werkzeug:127.0.0.1 - - [17/Jul/2022 15:11:48] "[33mGET /favicon.ico HTTP/1.1[0m" 404 -
127.0.0.1 - - [17/Jul/2022 15:11:48] "[33mGET /favicon.ico HTTP/1.1[0m" 404 -
INFO:werkzeug:127.0.0.1 - - [17/Jul/2022 15:11:50] "GET /search?s=кто HTTP/1.1" 200 -
127.0.0.1 - - [17/Jul/2022 15:11:50] "GET /search?s=кто HTTP/1.1" 200 -
INFO:werkzeug:127.0.0.1 - - [17/Jul/2022 15:11:50] "[36mGET /static/styles.min.css HTTP/1.1[0m" 304 -
127.0.0.1 - - [17/Jul/2022 15:11:50] "[36mGET /static/styles.min.css HTTP/1.1[0m" 304 -
INFO:werkzeug:127.0.0.1 - - [17/Jul/2022 15:11:53] "GET /search?s=ежи HTTP/1.1" 200 -
127.0.0.1 - - [17/Jul/2022 15:11:53] "GET /search?s=ежи HTTP/1.1" 200 -
INFO:werkzeug:127.0.0.1 - - [17/Jul/2022 15:11:53] "[36mGET /static/styles.min.css HTTP/1.1[0m" 304 -
127.0.0.1 - - [17/Jul/2022 15:11:53] "[36mGET /static/styles.min.css HTTP/1.1[0m" 304 -
INFO:werkzeug:127.0.0.1 - - [17/Jul/2022 15:11:56] "GET /search?s=мы HTTP/1.1" 200 -
127.0.0.1 - - [17/Jul/2022 15:11:56] "GET /search?s=мы HTTP/1.1" 200 -
INFO:werkzeug:127.0.0.1 - - [17/Jul/2022 15:11:56] "[36mGET /static/styles.min.css HTTP/1.1[0m" 304 -
127.0.0.1 - - [17/Jul/2022 15:11:56] "[36mGET /static/styles.min.css HTTP/1.1[0m" 304 -
INFO:werkzeug:127.0.0.1 - - [17/Jul/2022 15:11:59] "GET /search?s=еда HTTP/1.1" 200 -
127.0.0.1 - - [17/Jul/2022 15:11:59] "GET /search?s=еда HTTP/1.1" 200 -
INFO:werkzeug:127.0.0.1 - - [17/Jul/2022 15:11:59] "[36mGET /static/styles.min.css HTTP/1.1[0m" 304 -
127.0.0.1 - - [17/Jul/2022 15:11:59] "[36mGET /static/styles.min.css HTTP/1.1[0m" 304 -
INFO:werkzeug:127.0.0.1 - - [17/Jul/2022 15:12:05] "GET /users/leo HTTP/1.1" 200 -
127.0.0.1 - - [17/Jul/2022 15:12:05] "GET /users/leo HTTP/1.1" 200 -
INFO:werkzeug:127.0.0.1 - - [17/Jul/2022 15:12:05] "[36mGET /static/styles.min.css HTTP/1.1[0m" 304 -
127.0.0.1 - - [17/Jul/2022 15:12:05] "[36mGET /static/styles.min.css HTTP/1.1[0m" 304 -
INFO:werkzeug:127.0.0.1 - - [17/Jul/2022 15:12:08] "GET /posts/1 HTTP/1.1" 200 -
127.0.0.1 - - [17/Jul/2022 15:12:08] "GET /posts/1 HTTP/1.1" 200 -
INFO:werkzeug:127.0.0.1 - - [17/Jul/2022 15:12:08] "[33mGET /img/bookmark.png HTTP/1.1[0m" 404 -
127.0.0.1 - - [17/Jul/2022 15:12:08] "[33mGET /img/bookmark.png HTTP/1.1[0m" 404 -
INFO:werkzeug:127.0.0.1 - - [17/Jul/2022 15:12:08] "[36mGET /static/styles.min.css HTTP/1.1[0m" 304 -
127.0.0.1 - - [17/Jul/2022 15:12:08] "[36mGET /static/styles.min.css HTTP/1.1[0m" 304 -
INFO:werkzeug:127.0.0.1 - - [17/Jul/2022 15:12:12] "GET / HTTP/1.1" 200 -
127.0.0.1 - - [17/Jul/2022 15:12:12] "GET / HTTP/1.1" 200 -
INFO:werkzeug:127.0.0.1 - - [17/Jul/2022 15:12:12] "[36mGET /static/styles.min.css HTTP/1.1[0m" 304 -
127.0.0.1 - - [17/Jul/2022 15:12:12] "[36mGET /static/styles.min.css HTTP/1.1[0m" 304 -
INFO:werkzeug:127.0.0.1 - - [17/Jul/2022 15:12:18] "GET / HTTP/1.1" 200 -
127.0.0.1 - - [17/Jul/2022 15:12:18] "GET / HTTP/1.1" 200 -
INFO:werkzeug:127.0.0.1 - - [17/Jul/2022 15:12:18] "[36mGET /static/styles.min.css HTTP/1.1[0m" 304 -
127.0.0.1 - - [17/Jul/2022 15:12:18] "[36mGET /static/styles.min.css HTTP/1.1[0m" 304 -
INFO:werkzeug:127.0.0.1 - - [17/Jul/2022 15:12:21] "GET /users/leo HTTP/1.1" 200 -
127.0.0.1 - - [17/Jul/2022 15:12:21] "GET /users/leo HTTP/1.1" 200 -
INFO:werkzeug:127.0.0.1 - - [17/Jul/2022 15:12:22] "[36mGET /static/styles.min.css HTTP/1.1[0m" 304 -
127.0.0.1 - - [17/Jul/2022 15:12:22] "[36mGET /static/styles.min.css HTTP/1.1[0m" 304 -
INFO:werkzeug:127.0.0.1 - - [17/Jul/2022 15:12:26] "GET /users/leo HTTP/1.1" 200 -
127.0.0.1 - - [17/Jul/2022 15:12:26] "GET /users/leo HTTP/1.1" 200 -
INFO:werkzeug:127.0.0.1 - - [17/Jul/2022 15:12:26] "[36mGET /static/styles.min.css HTTP/1.1[0m" 304 -
127.0.0.1 - - [17/Jul/2022 15:12:26] "[36mGET /static/styles.min.css HTTP/1.1[0m" 304 -
INFO:werkzeug:127.0.0.1 - - [17/Jul/2022 15:12:27] "GET /users/leo HTTP/1.1" 200 -
127.0.0.1 - - [17/Jul/2022 15:12:27] "GET /users/leo HTTP/1.1" 200 -
INFO:werkzeug:127.0.0.1 - - [17/Jul/2022 15:12:27] "[36mGET /static/styles.min.css HTTP/1.1[0m" 304 -
127.0.0.1 - - [17/Jul/2022 15:12:27] "[36mGET /static/styles.min.css HTTP/1.1[0m" 304 -
INFO:werkzeug:127.0.0.1 - - [17/Jul/2022 15:12:28] "GET /users/leo HTTP/1.1" 200 -
127.0.0.1 - - [17/Jul/2022 15:12:28] "GET /users/leo HTTP/1.1" 200 -
INFO:werkzeug:127.0.0.1 - - [17/Jul/2022 15:12:28] "[36mGET /static/styles.min.css HTTP/1.1[0m" 304 -
127.0.0.1 - - [17/Jul/2022 15:12:28] "[36mGET /static/styles.min.css HTTP/1.1[0m" 304 -
INFO:werkzeug:127.0.0.1 - - [17/Jul/2022 15:12:31] "GET / HTTP/1.1" 200 -
127.0.0.1 - - [17/Jul/2022 15:12:31] "GET / HTTP/1.1" 200 -
INFO:werkzeug:127.0.0.1 - - [17/Jul/2022 15:12:31] "[36mGET /static/styles.min.css HTTP/1.1[0m" 304 -
127.0.0.1 - - [17/Jul/2022 15:12:31] "[36mGET /static/styles.min.css HTTP/1.1[0m" 304 -
INFO:werkzeug:127.0.0.1 - - [17/Jul/2022 15:12:36] "GET / HTTP/1.1" 200 -
127.0.0.1 - - [17/Jul/2022 15:12:36] "GET / HTTP/1.1" 200 -
INFO:werkzeug:127.0.0.1 - - [17/Jul/2022 15:12:36] "[36mGET /static/styles.min.css HTTP/1.1[0m" 304 -
127.0.0.1 - - [17/Jul/2022 15:12:36] "[36mGET /static/styles.min.css HTTP/1.1[0m" 304 -
INFO:werkzeug:127.0.0.1 - - [17/Jul/2022 15:12:39] "GET / HTTP/1.1" 200 -
127.0.0.1 - - [17/Jul/2022 15:12:39] "GET / HTTP/1.1" 200 -
INFO:werkzeug:127.0.0.1 - - [17/Jul/2022 15:12:39] "[36mGET /static/styles.min.css HTTP/1.1[0m" 304 -
127.0.0.1 - - [17/Jul/2022 15:12:39] "[36mGET /static/styles.min.css HTTP/1.1[0m" 304 -
INFO:werkzeug:127.0.0.1 - - [17/Jul/2022 15:12:39] "GET / HTTP/1.1" 200 -
127.0.0.1 - - [17/Jul/2022 15:12:39] "GET / HTTP/1.1" 200 -
INFO:werkzeug:127.0.0.1 - - [17/Jul/2022 15:12:39] "[36mGET /static/styles.min.css HTTP/1.1[0m" 304 -
127.0.0.1 - - [17/Jul/2022 15:12:39] "[36mGET /static/styles.min.css HTTP/1.1[0m" 304 -
INFO:werkzeug:127.0.0.1 - - [17/Jul/2022 15:12:41] "GET /search HTTP/1.1" 200 -
127.0.0.1 - - [17/Jul/2022 15:12:41] "GET /search HTTP/1.1" 200 -
INFO:werkzeug:127.0.0.1 - - [17/Jul/2022 15:12:41] "[36mGET /static/styles.min.css HTTP/1.1[0m" 304 -
127.0.0.1 - - [17/Jul/2022 15:12:41] "[36mGET /static/styles.min.css HTTP/1.1[0m" 304 -
INFO:werkzeug:127.0.0.1 - - [17/Jul/2022 15:12:43] "GET / HTTP/1.1" 200 -
127.0.0.1 - - [17/Jul/2022 15:12:43] "GET / HTTP/1.1" 200 -
INFO:werkzeug:127.0.0.1 - - [17/Jul/2022 15:12:43] "[36mGET /static/styles.min.css HTTP/1.1[0m" 304 -
127.0.0.1 - - [17/Jul/2022 15:12:43] "[36mGET /static/styles.min.css HTTP/1.1[0m" 304 -
INFO:werkzeug:127.0.0.1 - - [17/Jul/2022 15:14:16] "[33mGET /api/ HTTP/1.1[0m" 404 -
127.0.0.1 - - [17/Jul/2022 15:14:16] "[33mGET /api/ HTTP/1.1[0m" 404 -
INFO:werkzeug:127.0.0.1 - - [17/Jul/2022 15:14:22] "GET /api/posts HTTP/1.1" 200 -
127.0.0.1 - - [17/Jul/2022 15:14:22] "GET /api/posts HTTP/1.1" 200 -
INFO:werkzeug: * Running on http://127.0.0.1:5000 (Press CTRL+C to quit)
 * Running on http://127.0.0.1:5000 (Press CTRL+C to quit)
INFO:werkzeug:127.0.0.1 - - [17/Jul/2022 15:14:59] "GET /api/posts HTTP/1.1" 200 -
127.0.0.1 - - [17/Jul/2022 15:14:59] "GET /api/posts HTTP/1.1" 200 -
INFO:werkzeug:127.0.0.1 - - [17/Jul/2022 15:15:00] "[33mGET /favicon.ico HTTP/1.1[0m" 404 -
127.0.0.1 - - [17/Jul/2022 15:15:00] "[33mGET /favicon.ico HTTP/1.1[0m" 404 -
INFO:werkzeug:127.0.0.1 - - [17/Jul/2022 15:15:13] "GET / HTTP/1.1" 200 -
127.0.0.1 - - [17/Jul/2022 15:15:13] "GET / HTTP/1.1" 200 -
INFO:werkzeug:127.0.0.1 - - [17/Jul/2022 15:15:14] "[36mGET /static/styles.min.css HTTP/1.1[0m" 304 -
127.0.0.1 - - [17/Jul/2022 15:15:14] "[36mGET /static/styles.min.css HTTP/1.1[0m" 304 -
INFO:werkzeug: * Running on http://127.0.0.1:5000 (Press CTRL+C to quit)
 * Running on http://127.0.0.1:5000 (Press CTRL+C to quit)
ERROR:app.run:Exception on / [GET]
Traceback (most recent call last):
  File "C:\Users\Павел\PycharmProjects\homeCourse2\FLASK\lib\site-packages\flask\app.py", line 2077, in wsgi_app
    response = self.full_dispatch_request()
  File "C:\Users\Павел\PycharmProjects\homeCourse2\FLASK\lib\site-packages\flask\app.py", line 1525, in full_dispatch_request
    rv = self.handle_user_exception(e)
  File "C:\Users\Павел\PycharmProjects\homeCourse2\FLASK\lib\site-packages\flask\app.py", line 1523, in full_dispatch_request
    rv = self.dispatch_request()
  File "C:\Users\Павел\PycharmProjects\homeCourse2\FLASK\lib\site-packages\flask\app.py", line 1509, in dispatch_request
    return self.ensure_sync(self.view_functions[rule.endpoint])(**req.view_args)
  File "C:\Users\Павел\PycharmProjects\homeCourse2\app\main\views.py", line 10, in page_index
    return render_template('index.html', posts= post)
  File "C:\Users\Павел\PycharmProjects\homeCourse2\FLASK\lib\site-packages\flask\templating.py", line 149, in render_template
    ctx.app.jinja_env.get_or_select_template(template_name_or_list),
  File "C:\Users\Павел\PycharmProjects\homeCourse2\FLASK\lib\site-packages\jinja2\environment.py", line 1081, in get_or_select_template
    return self.get_template(template_name_or_list, parent, globals)
  File "C:\Users\Павел\PycharmProjects\homeCourse2\FLASK\lib\site-packages\jinja2\environment.py", line 1010, in get_template
    return self._load_template(name, globals)
  File "C:\Users\Павел\PycharmProjects\homeCourse2\FLASK\lib\site-packages\jinja2\environment.py", line 969, in _load_template
    template = self.loader.load(self, name, self.make_globals(globals))
  File "C:\Users\Павел\PycharmProjects\homeCourse2\FLASK\lib\site-packages\jinja2\loaders.py", line 138, in load
    code = environment.compile(source, name, filename)
  File "C:\Users\Павел\PycharmProjects\homeCourse2\FLASK\lib\site-packages\jinja2\environment.py", line 768, in compile
    self.handle_exception(source=source_hint)
  File "C:\Users\Павел\PycharmProjects\homeCourse2\FLASK\lib\site-packages\jinja2\environment.py", line 936, in handle_exception
    raise rewrite_traceback_stack(source=source)
  File "C:\Users\Павел\PycharmProjects\homeCourse2\app\main\templates\index.html", line 62, in template
    {% endfor %}
jinja2.exceptions.TemplateSyntaxError: Encountered unknown tag 'endfor'.
Exception on / [GET]
Traceback (most recent call last):
  File "C:\Users\Павел\PycharmProjects\homeCourse2\FLASK\lib\site-packages\flask\app.py", line 2077, in wsgi_app
    response = self.full_dispatch_request()
  File "C:\Users\Павел\PycharmProjects\homeCourse2\FLASK\lib\site-packages\flask\app.py", line 1525, in full_dispatch_request
    rv = self.handle_user_exception(e)
  File "C:\Users\Павел\PycharmProjects\homeCourse2\FLASK\lib\site-packages\flask\app.py", line 1523, in full_dispatch_request
    rv = self.dispatch_request()
  File "C:\Users\Павел\PycharmProjects\homeCourse2\FLASK\lib\site-packages\flask\app.py", line 1509, in dispatch_request
    return self.ensure_sync(self.view_functions[rule.endpoint])(**req.view_args)
  File "C:\Users\Павел\PycharmProjects\homeCourse2\app\main\views.py", line 10, in page_index
    return render_template('index.html', posts= post)
  File "C:\Users\Павел\PycharmProjects\homeCourse2\FLASK\lib\site-packages\flask\templating.py", line 149, in render_template
    ctx.app.jinja_env.get_or_select_template(template_name_or_list),
  File "C:\Users\Павел\PycharmProjects\homeCourse2\FLASK\lib\site-packages\jinja2\environment.py", line 1081, in get_or_select_template
    return self.get_template(template_name_or_list, parent, globals)
  File "C:\Users\Павел\PycharmProjects\homeCourse2\FLASK\lib\site-packages\jinja2\environment.py", line 1010, in get_template
    return self._load_template(name, globals)
  File "C:\Users\Павел\PycharmProjects\homeCourse2\FLASK\lib\site-packages\jinja2\environment.py", line 969, in _load_template
    template = self.loader.load(self, name, self.make_globals(globals))
  File "C:\Users\Павел\PycharmProjects\homeCourse2\FLASK\lib\site-packages\jinja2\loaders.py", line 138, in load
    code = environment.compile(source, name, filename)
  File "C:\Users\Павел\PycharmProjects\homeCourse2\FLASK\lib\site-packages\jinja2\environment.py", line 768, in compile
    self.handle_exception(source=source_hint)
  File "C:\Users\Павел\PycharmProjects\homeCourse2\FLASK\lib\site-packages\jinja2\environment.py", line 936, in handle_exception
    raise rewrite_traceback_stack(source=source)
  File "C:\Users\Павел\PycharmProjects\homeCourse2\app\main\templates\index.html", line 62, in template
    {% endfor %}
jinja2.exceptions.TemplateSyntaxError: Encountered unknown tag 'endfor'.
INFO:werkzeug:127.0.0.1 - - [17/Jul/2022 15:16:56] "[35m[1mGET / HTTP/1.1[0m" 500 -
127.0.0.1 - - [17/Jul/2022 15:16:56] "[35m[1mGET / HTTP/1.1[0m" 500 -
ERROR:app.run:Exception on / [GET]
Traceback (most recent call last):
  File "C:\Users\Павел\PycharmProjects\homeCourse2\FLASK\lib\site-packages\flask\app.py", line 2077, in wsgi_app
    response = self.full_dispatch_request()
  File "C:\Users\Павел\PycharmProjects\homeCourse2\FLASK\lib\site-packages\flask\app.py", line 1525, in full_dispatch_request
    rv = self.handle_user_exception(e)
  File "C:\Users\Павел\PycharmProjects\homeCourse2\FLASK\lib\site-packages\flask\app.py", line 1523, in full_dispatch_request
    rv = self.dispatch_request()
  File "C:\Users\Павел\PycharmProjects\homeCourse2\FLASK\lib\site-packages\flask\app.py", line 1509, in dispatch_request
    return self.ensure_sync(self.view_functions[rule.endpoint])(**req.view_args)
  File "C:\Users\Павел\PycharmProjects\homeCourse2\app\main\views.py", line 10, in page_index
    return render_template('index.html', posts= post)
  File "C:\Users\Павел\PycharmProjects\homeCourse2\FLASK\lib\site-packages\flask\templating.py", line 149, in render_template
    ctx.app.jinja_env.get_or_select_template(template_name_or_list),
  File "C:\Users\Павел\PycharmProjects\homeCourse2\FLASK\lib\site-packages\jinja2\environment.py", line 1081, in get_or_select_template
    return self.get_template(template_name_or_list, parent, globals)
  File "C:\Users\Павел\PycharmProjects\homeCourse2\FLASK\lib\site-packages\jinja2\environment.py", line 1010, in get_template
    return self._load_template(name, globals)
  File "C:\Users\Павел\PycharmProjects\homeCourse2\FLASK\lib\site-packages\jinja2\environment.py", line 969, in _load_template
    template = self.loader.load(self, name, self.make_globals(globals))
  File "C:\Users\Павел\PycharmProjects\homeCourse2\FLASK\lib\site-packages\jinja2\loaders.py", line 138, in load
    code = environment.compile(source, name, filename)
  File "C:\Users\Павел\PycharmProjects\homeCourse2\FLASK\lib\site-packages\jinja2\environment.py", line 768, in compile
    self.handle_exception(source=source_hint)
  File "C:\Users\Павел\PycharmProjects\homeCourse2\FLASK\lib\site-packages\jinja2\environment.py", line 936, in handle_exception
    raise rewrite_traceback_stack(source=source)
  File "C:\Users\Павел\PycharmProjects\homeCourse2\app\main\templates\index.html", line 62, in template
    {% endfor %}
jinja2.exceptions.TemplateSyntaxError: Encountered unknown tag 'endfor'.
Exception on / [GET]
Traceback (most recent call last):
  File "C:\Users\Павел\PycharmProjects\homeCourse2\FLASK\lib\site-packages\flask\app.py", line 2077, in wsgi_app
    response = self.full_dispatch_request()
  File "C:\Users\Павел\PycharmProjects\homeCourse2\FLASK\lib\site-packages\flask\app.py", line 1525, in full_dispatch_request
    rv = self.handle_user_exception(e)
  File "C:\Users\Павел\PycharmProjects\homeCourse2\FLASK\lib\site-packages\flask\app.py", line 1523, in full_dispatch_request
    rv = self.dispatch_request()
  File "C:\Users\Павел\PycharmProjects\homeCourse2\FLASK\lib\site-packages\flask\app.py", line 1509, in dispatch_request
    return self.ensure_sync(self.view_functions[rule.endpoint])(**req.view_args)
  File "C:\Users\Павел\PycharmProjects\homeCourse2\app\main\views.py", line 10, in page_index
    return render_template('index.html', posts= post)
  File "C:\Users\Павел\PycharmProjects\homeCourse2\FLASK\lib\site-packages\flask\templating.py", line 149, in render_template
    ctx.app.jinja_env.get_or_select_template(template_name_or_list),
  File "C:\Users\Павел\PycharmProjects\homeCourse2\FLASK\lib\site-packages\jinja2\environment.py", line 1081, in get_or_select_template
    return self.get_template(template_name_or_list, parent, globals)
  File "C:\Users\Павел\PycharmProjects\homeCourse2\FLASK\lib\site-packages\jinja2\environment.py", line 1010, in get_template
    return self._load_template(name, globals)
  File "C:\Users\Павел\PycharmProjects\homeCourse2\FLASK\lib\site-packages\jinja2\environment.py", line 969, in _load_template
    template = self.loader.load(self, name, self.make_globals(globals))
  File "C:\Users\Павел\PycharmProjects\homeCourse2\FLASK\lib\site-packages\jinja2\loaders.py", line 138, in load
    code = environment.compile(source, name, filename)
  File "C:\Users\Павел\PycharmProjects\homeCourse2\FLASK\lib\site-packages\jinja2\environment.py", line 768, in compile
    self.handle_exception(source=source_hint)
  File "C:\Users\Павел\PycharmProjects\homeCourse2\FLASK\lib\site-packages\jinja2\environment.py", line 936, in handle_exception
    raise rewrite_traceback_stack(source=source)
  File "C:\Users\Павел\PycharmProjects\homeCourse2\app\main\templates\index.html", line 62, in template
    {% endfor %}
jinja2.exceptions.TemplateSyntaxError: Encountered unknown tag 'endfor'.
INFO:werkzeug:127.0.0.1 - - [17/Jul/2022 15:16:58] "[35m[1mGET / HTTP/1.1[0m" 500 -
127.0.0.1 - - [17/Jul/2022 15:16:58] "[35m[1mGET / HTTP/1.1[0m" 500 -
ERROR:app.run:Exception on / [GET]
Traceback (most recent call last):
  File "C:\Users\Павел\PycharmProjects\homeCourse2\FLASK\lib\site-packages\flask\app.py", line 2077, in wsgi_app
    response = self.full_dispatch_request()
  File "C:\Users\Павел\PycharmProjects\homeCourse2\FLASK\lib\site-packages\flask\app.py", line 1525, in full_dispatch_request
    rv = self.handle_user_exception(e)
  File "C:\Users\Павел\PycharmProjects\homeCourse2\FLASK\lib\site-packages\flask\app.py", line 1523, in full_dispatch_request
    rv = self.dispatch_request()
  File "C:\Users\Павел\PycharmProjects\homeCourse2\FLASK\lib\site-packages\flask\app.py", line 1509, in dispatch_request
    return self.ensure_sync(self.view_functions[rule.endpoint])(**req.view_args)
  File "C:\Users\Павел\PycharmProjects\homeCourse2\app\main\views.py", line 10, in page_index
    return render_template('index.html', posts= post)
  File "C:\Users\Павел\PycharmProjects\homeCourse2\FLASK\lib\site-packages\flask\templating.py", line 149, in render_template
    ctx.app.jinja_env.get_or_select_template(template_name_or_list),
  File "C:\Users\Павел\PycharmProjects\homeCourse2\FLASK\lib\site-packages\jinja2\environment.py", line 1081, in get_or_select_template
    return self.get_template(template_name_or_list, parent, globals)
  File "C:\Users\Павел\PycharmProjects\homeCourse2\FLASK\lib\site-packages\jinja2\environment.py", line 1010, in get_template
    return self._load_template(name, globals)
  File "C:\Users\Павел\PycharmProjects\homeCourse2\FLASK\lib\site-packages\jinja2\environment.py", line 969, in _load_template
    template = self.loader.load(self, name, self.make_globals(globals))
  File "C:\Users\Павел\PycharmProjects\homeCourse2\FLASK\lib\site-packages\jinja2\loaders.py", line 138, in load
    code = environment.compile(source, name, filename)
  File "C:\Users\Павел\PycharmProjects\homeCourse2\FLASK\lib\site-packages\jinja2\environment.py", line 768, in compile
    self.handle_exception(source=source_hint)
  File "C:\Users\Павел\PycharmProjects\homeCourse2\FLASK\lib\site-packages\jinja2\environment.py", line 936, in handle_exception
    raise rewrite_traceback_stack(source=source)
  File "C:\Users\Павел\PycharmProjects\homeCourse2\app\main\templates\index.html", line 62, in template
    {% endfor %}
jinja2.exceptions.TemplateSyntaxError: Encountered unknown tag 'endfor'.
Exception on / [GET]
Traceback (most recent call last):
  File "C:\Users\Павел\PycharmProjects\homeCourse2\FLASK\lib\site-packages\flask\app.py", line 2077, in wsgi_app
    response = self.full_dispatch_request()
  File "C:\Users\Павел\PycharmProjects\homeCourse2\FLASK\lib\site-packages\flask\app.py", line 1525, in full_dispatch_request
    rv = self.handle_user_exception(e)
  File "C:\Users\Павел\PycharmProjects\homeCourse2\FLASK\lib\site-packages\flask\app.py", line 1523, in full_dispatch_request
    rv = self.dispatch_request()
  File "C:\Users\Павел\PycharmProjects\homeCourse2\FLASK\lib\site-packages\flask\app.py", line 1509, in dispatch_request
    return self.ensure_sync(self.view_functions[rule.endpoint])(**req.view_args)
  File "C:\Users\Павел\PycharmProjects\homeCourse2\app\main\views.py", line 10, in page_index
    return render_template('index.html', posts= post)
  File "C:\Users\Павел\PycharmProjects\homeCourse2\FLASK\lib\site-packages\flask\templating.py", line 149, in render_template
    ctx.app.jinja_env.get_or_select_template(template_name_or_list),
  File "C:\Users\Павел\PycharmProjects\homeCourse2\FLASK\lib\site-packages\jinja2\environment.py", line 1081, in get_or_select_template
    return self.get_template(template_name_or_list, parent, globals)
  File "C:\Users\Павел\PycharmProjects\homeCourse2\FLASK\lib\site-packages\jinja2\environment.py", line 1010, in get_template
    return self._load_template(name, globals)
  File "C:\Users\Павел\PycharmProjects\homeCourse2\FLASK\lib\site-packages\jinja2\environment.py", line 969, in _load_template
    template = self.loader.load(self, name, self.make_globals(globals))
  File "C:\Users\Павел\PycharmProjects\homeCourse2\FLASK\lib\site-packages\jinja2\loaders.py", line 138, in load
    code = environment.compile(source, name, filename)
  File "C:\Users\Павел\PycharmProjects\homeCourse2\FLASK\lib\site-packages\jinja2\environment.py", line 768, in compile
    self.handle_exception(source=source_hint)
  File "C:\Users\Павел\PycharmProjects\homeCourse2\FLASK\lib\site-packages\jinja2\environment.py", line 936, in handle_exception
    raise rewrite_traceback_stack(source=source)
  File "C:\Users\Павел\PycharmProjects\homeCourse2\app\main\templates\index.html", line 62, in template
    {% endfor %}
jinja2.exceptions.TemplateSyntaxError: Encountered unknown tag 'endfor'.
INFO:werkzeug:127.0.0.1 - - [17/Jul/2022 15:16:59] "[35m[1mGET / HTTP/1.1[0m" 500 -
127.0.0.1 - - [17/Jul/2022 15:16:59] "[35m[1mGET / HTTP/1.1[0m" 500 -
ERROR:app.run:Exception on / [GET]
Traceback (most recent call last):
  File "C:\Users\Павел\PycharmProjects\homeCourse2\FLASK\lib\site-packages\flask\app.py", line 2077, in wsgi_app
    response = self.full_dispatch_request()
  File "C:\Users\Павел\PycharmProjects\homeCourse2\FLASK\lib\site-packages\flask\app.py", line 1525, in full_dispatch_request
    rv = self.handle_user_exception(e)
  File "C:\Users\Павел\PycharmProjects\homeCourse2\FLASK\lib\site-packages\flask\app.py", line 1523, in full_dispatch_request
    rv = self.dispatch_request()
  File "C:\Users\Павел\PycharmProjects\homeCourse2\FLASK\lib\site-packages\flask\app.py", line 1509, in dispatch_request
    return self.ensure_sync(self.view_functions[rule.endpoint])(**req.view_args)
  File "C:\Users\Павел\PycharmProjects\homeCourse2\app\main\views.py", line 10, in page_index
    return render_template('index.html', posts= post)
  File "C:\Users\Павел\PycharmProjects\homeCourse2\FLASK\lib\site-packages\flask\templating.py", line 149, in render_template
    ctx.app.jinja_env.get_or_select_template(template_name_or_list),
  File "C:\Users\Павел\PycharmProjects\homeCourse2\FLASK\lib\site-packages\jinja2\environment.py", line 1081, in get_or_select_template
    return self.get_template(template_name_or_list, parent, globals)
  File "C:\Users\Павел\PycharmProjects\homeCourse2\FLASK\lib\site-packages\jinja2\environment.py", line 1010, in get_template
    return self._load_template(name, globals)
  File "C:\Users\Павел\PycharmProjects\homeCourse2\FLASK\lib\site-packages\jinja2\environment.py", line 969, in _load_template
    template = self.loader.load(self, name, self.make_globals(globals))
  File "C:\Users\Павел\PycharmProjects\homeCourse2\FLASK\lib\site-packages\jinja2\loaders.py", line 138, in load
    code = environment.compile(source, name, filename)
  File "C:\Users\Павел\PycharmProjects\homeCourse2\FLASK\lib\site-packages\jinja2\environment.py", line 768, in compile
    self.handle_exception(source=source_hint)
  File "C:\Users\Павел\PycharmProjects\homeCourse2\FLASK\lib\site-packages\jinja2\environment.py", line 936, in handle_exception
    raise rewrite_traceback_stack(source=source)
  File "C:\Users\Павел\PycharmProjects\homeCourse2\app\main\templates\index.html", line 62, in template
    {% endfor %}
jinja2.exceptions.TemplateSyntaxError: Encountered unknown tag 'endfor'.
Exception on / [GET]
Traceback (most recent call last):
  File "C:\Users\Павел\PycharmProjects\homeCourse2\FLASK\lib\site-packages\flask\app.py", line 2077, in wsgi_app
    response = self.full_dispatch_request()
  File "C:\Users\Павел\PycharmProjects\homeCourse2\FLASK\lib\site-packages\flask\app.py", line 1525, in full_dispatch_request
    rv = self.handle_user_exception(e)
  File "C:\Users\Павел\PycharmProjects\homeCourse2\FLASK\lib\site-packages\flask\app.py", line 1523, in full_dispatch_request
    rv = self.dispatch_request()
  File "C:\Users\Павел\PycharmProjects\homeCourse2\FLASK\lib\site-packages\flask\app.py", line 1509, in dispatch_request
    return self.ensure_sync(self.view_functions[rule.endpoint])(**req.view_args)
  File "C:\Users\Павел\PycharmProjects\homeCourse2\app\main\views.py", line 10, in page_index
    return render_template('index.html', posts= post)
  File "C:\Users\Павел\PycharmProjects\homeCourse2\FLASK\lib\site-packages\flask\templating.py", line 149, in render_template
    ctx.app.jinja_env.get_or_select_template(template_name_or_list),
  File "C:\Users\Павел\PycharmProjects\homeCourse2\FLASK\lib\site-packages\jinja2\environment.py", line 1081, in get_or_select_template
    return self.get_template(template_name_or_list, parent, globals)
  File "C:\Users\Павел\PycharmProjects\homeCourse2\FLASK\lib\site-packages\jinja2\environment.py", line 1010, in get_template
    return self._load_template(name, globals)
  File "C:\Users\Павел\PycharmProjects\homeCourse2\FLASK\lib\site-packages\jinja2\environment.py", line 969, in _load_template
    template = self.loader.load(self, name, self.make_globals(globals))
  File "C:\Users\Павел\PycharmProjects\homeCourse2\FLASK\lib\site-packages\jinja2\loaders.py", line 138, in load
    code = environment.compile(source, name, filename)
  File "C:\Users\Павел\PycharmProjects\homeCourse2\FLASK\lib\site-packages\jinja2\environment.py", line 768, in compile
    self.handle_exception(source=source_hint)
  File "C:\Users\Павел\PycharmProjects\homeCourse2\FLASK\lib\site-packages\jinja2\environment.py", line 936, in handle_exception
    raise rewrite_traceback_stack(source=source)
  File "C:\Users\Павел\PycharmProjects\homeCourse2\app\main\templates\index.html", line 62, in template
    {% endfor %}
jinja2.exceptions.TemplateSyntaxError: Encountered unknown tag 'endfor'.
INFO:werkzeug:127.0.0.1 - - [17/Jul/2022 15:17:09] "[35m[1mGET / HTTP/1.1[0m" 500 -
127.0.0.1 - - [17/Jul/2022 15:17:09] "[35m[1mGET / HTTP/1.1[0m" 500 -
ERROR:app.run:Exception on / [GET]
Traceback (most recent call last):
  File "C:\Users\Павел\PycharmProjects\homeCourse2\FLASK\lib\site-packages\flask\app.py", line 2077, in wsgi_app
    response = self.full_dispatch_request()
  File "C:\Users\Павел\PycharmProjects\homeCourse2\FLASK\lib\site-packages\flask\app.py", line 1525, in full_dispatch_request
    rv = self.handle_user_exception(e)
  File "C:\Users\Павел\PycharmProjects\homeCourse2\FLASK\lib\site-packages\flask\app.py", line 1523, in full_dispatch_request
    rv = self.dispatch_request()
  File "C:\Users\Павел\PycharmProjects\homeCourse2\FLASK\lib\site-packages\flask\app.py", line 1509, in dispatch_request
    return self.ensure_sync(self.view_functions[rule.endpoint])(**req.view_args)
  File "C:\Users\Павел\PycharmProjects\homeCourse2\app\main\views.py", line 10, in page_index
    return render_template('index.html', posts= post)
  File "C:\Users\Павел\PycharmProjects\homeCourse2\FLASK\lib\site-packages\flask\templating.py", line 149, in render_template
    ctx.app.jinja_env.get_or_select_template(template_name_or_list),
  File "C:\Users\Павел\PycharmProjects\homeCourse2\FLASK\lib\site-packages\jinja2\environment.py", line 1081, in get_or_select_template
    return self.get_template(template_name_or_list, parent, globals)
  File "C:\Users\Павел\PycharmProjects\homeCourse2\FLASK\lib\site-packages\jinja2\environment.py", line 1010, in get_template
    return self._load_template(name, globals)
  File "C:\Users\Павел\PycharmProjects\homeCourse2\FLASK\lib\site-packages\jinja2\environment.py", line 969, in _load_template
    template = self.loader.load(self, name, self.make_globals(globals))
  File "C:\Users\Павел\PycharmProjects\homeCourse2\FLASK\lib\site-packages\jinja2\loaders.py", line 138, in load
    code = environment.compile(source, name, filename)
  File "C:\Users\Павел\PycharmProjects\homeCourse2\FLASK\lib\site-packages\jinja2\environment.py", line 768, in compile
    self.handle_exception(source=source_hint)
  File "C:\Users\Павел\PycharmProjects\homeCourse2\FLASK\lib\site-packages\jinja2\environment.py", line 936, in handle_exception
    raise rewrite_traceback_stack(source=source)
  File "C:\Users\Павел\PycharmProjects\homeCourse2\app\main\templates\index.html", line 62, in template
    {% endfor %}
jinja2.exceptions.TemplateSyntaxError: Encountered unknown tag 'endfor'.
Exception on / [GET]
Traceback (most recent call last):
  File "C:\Users\Павел\PycharmProjects\homeCourse2\FLASK\lib\site-packages\flask\app.py", line 2077, in wsgi_app
    response = self.full_dispatch_request()
  File "C:\Users\Павел\PycharmProjects\homeCourse2\FLASK\lib\site-packages\flask\app.py", line 1525, in full_dispatch_request
    rv = self.handle_user_exception(e)
  File "C:\Users\Павел\PycharmProjects\homeCourse2\FLASK\lib\site-packages\flask\app.py", line 1523, in full_dispatch_request
    rv = self.dispatch_request()
  File "C:\Users\Павел\PycharmProjects\homeCourse2\FLASK\lib\site-packages\flask\app.py", line 1509, in dispatch_request
    return self.ensure_sync(self.view_functions[rule.endpoint])(**req.view_args)
  File "C:\Users\Павел\PycharmProjects\homeCourse2\app\main\views.py", line 10, in page_index
    return render_template('index.html', posts= post)
  File "C:\Users\Павел\PycharmProjects\homeCourse2\FLASK\lib\site-packages\flask\templating.py", line 149, in render_template
    ctx.app.jinja_env.get_or_select_template(template_name_or_list),
  File "C:\Users\Павел\PycharmProjects\homeCourse2\FLASK\lib\site-packages\jinja2\environment.py", line 1081, in get_or_select_template
    return self.get_template(template_name_or_list, parent, globals)
  File "C:\Users\Павел\PycharmProjects\homeCourse2\FLASK\lib\site-packages\jinja2\environment.py", line 1010, in get_template
    return self._load_template(name, globals)
  File "C:\Users\Павел\PycharmProjects\homeCourse2\FLASK\lib\site-packages\jinja2\environment.py", line 969, in _load_template
    template = self.loader.load(self, name, self.make_globals(globals))
  File "C:\Users\Павел\PycharmProjects\homeCourse2\FLASK\lib\site-packages\jinja2\loaders.py", line 138, in load
    code = environment.compile(source, name, filename)
  File "C:\Users\Павел\PycharmProjects\homeCourse2\FLASK\lib\site-packages\jinja2\environment.py", line 768, in compile
    self.handle_exception(source=source_hint)
  File "C:\Users\Павел\PycharmProjects\homeCourse2\FLASK\lib\site-packages\jinja2\environment.py", line 936, in handle_exception
    raise rewrite_traceback_stack(source=source)
  File "C:\Users\Павел\PycharmProjects\homeCourse2\app\main\templates\index.html", line 62, in template
    {% endfor %}
jinja2.exceptions.TemplateSyntaxError: Encountered unknown tag 'endfor'.
INFO:werkzeug:127.0.0.1 - - [17/Jul/2022 15:17:14] "[35m[1mGET / HTTP/1.1[0m" 500 -
127.0.0.1 - - [17/Jul/2022 15:17:14] "[35m[1mGET / HTTP/1.1[0m" 500 -
INFO:werkzeug: * Running on http://127.0.0.1:5000 (Press CTRL+C to quit)
 * Running on http://127.0.0.1:5000 (Press CTRL+C to quit)
ERROR:app.run:Exception on / [GET]
Traceback (most recent call last):
  File "C:\Users\Павел\PycharmProjects\homeCourse2\FLASK\lib\site-packages\flask\app.py", line 2077, in wsgi_app
    response = self.full_dispatch_request()
  File "C:\Users\Павел\PycharmProjects\homeCourse2\FLASK\lib\site-packages\flask\app.py", line 1525, in full_dispatch_request
    rv = self.handle_user_exception(e)
  File "C:\Users\Павел\PycharmProjects\homeCourse2\FLASK\lib\site-packages\flask\app.py", line 1523, in full_dispatch_request
    rv = self.dispatch_request()
  File "C:\Users\Павел\PycharmProjects\homeCourse2\FLASK\lib\site-packages\flask\app.py", line 1509, in dispatch_request
    return self.ensure_sync(self.view_functions[rule.endpoint])(**req.view_args)
  File "C:\Users\Павел\PycharmProjects\homeCourse2\app\main\views.py", line 10, in page_index
    return render_template('index.html', posts= post)
  File "C:\Users\Павел\PycharmProjects\homeCourse2\FLASK\lib\site-packages\flask\templating.py", line 149, in render_template
    ctx.app.jinja_env.get_or_select_template(template_name_or_list),
  File "C:\Users\Павел\PycharmProjects\homeCourse2\FLASK\lib\site-packages\jinja2\environment.py", line 1081, in get_or_select_template
    return self.get_template(template_name_or_list, parent, globals)
  File "C:\Users\Павел\PycharmProjects\homeCourse2\FLASK\lib\site-packages\jinja2\environment.py", line 1010, in get_template
    return self._load_template(name, globals)
  File "C:\Users\Павел\PycharmProjects\homeCourse2\FLASK\lib\site-packages\jinja2\environment.py", line 969, in _load_template
    template = self.loader.load(self, name, self.make_globals(globals))
  File "C:\Users\Павел\PycharmProjects\homeCourse2\FLASK\lib\site-packages\jinja2\loaders.py", line 138, in load
    code = environment.compile(source, name, filename)
  File "C:\Users\Павел\PycharmProjects\homeCourse2\FLASK\lib\site-packages\jinja2\environment.py", line 768, in compile
    self.handle_exception(source=source_hint)
  File "C:\Users\Павел\PycharmProjects\homeCourse2\FLASK\lib\site-packages\jinja2\environment.py", line 936, in handle_exception
    raise rewrite_traceback_stack(source=source)
  File "C:\Users\Павел\PycharmProjects\homeCourse2\app\main\templates\index.html", line 63, in template
    {% endfor %}
jinja2.exceptions.TemplateSyntaxError: Encountered unknown tag 'endfor'.
Exception on / [GET]
Traceback (most recent call last):
  File "C:\Users\Павел\PycharmProjects\homeCourse2\FLASK\lib\site-packages\flask\app.py", line 2077, in wsgi_app
    response = self.full_dispatch_request()
  File "C:\Users\Павел\PycharmProjects\homeCourse2\FLASK\lib\site-packages\flask\app.py", line 1525, in full_dispatch_request
    rv = self.handle_user_exception(e)
  File "C:\Users\Павел\PycharmProjects\homeCourse2\FLASK\lib\site-packages\flask\app.py", line 1523, in full_dispatch_request
    rv = self.dispatch_request()
  File "C:\Users\Павел\PycharmProjects\homeCourse2\FLASK\lib\site-packages\flask\app.py", line 1509, in dispatch_request
    return self.ensure_sync(self.view_functions[rule.endpoint])(**req.view_args)
  File "C:\Users\Павел\PycharmProjects\homeCourse2\app\main\views.py", line 10, in page_index
    return render_template('index.html', posts= post)
  File "C:\Users\Павел\PycharmProjects\homeCourse2\FLASK\lib\site-packages\flask\templating.py", line 149, in render_template
    ctx.app.jinja_env.get_or_select_template(template_name_or_list),
  File "C:\Users\Павел\PycharmProjects\homeCourse2\FLASK\lib\site-packages\jinja2\environment.py", line 1081, in get_or_select_template
    return self.get_template(template_name_or_list, parent, globals)
  File "C:\Users\Павел\PycharmProjects\homeCourse2\FLASK\lib\site-packages\jinja2\environment.py", line 1010, in get_template
    return self._load_template(name, globals)
  File "C:\Users\Павел\PycharmProjects\homeCourse2\FLASK\lib\site-packages\jinja2\environment.py", line 969, in _load_template
    template = self.loader.load(self, name, self.make_globals(globals))
  File "C:\Users\Павел\PycharmProjects\homeCourse2\FLASK\lib\site-packages\jinja2\loaders.py", line 138, in load
    code = environment.compile(source, name, filename)
  File "C:\Users\Павел\PycharmProjects\homeCourse2\FLASK\lib\site-packages\jinja2\environment.py", line 768, in compile
    self.handle_exception(source=source_hint)
  File "C:\Users\Павел\PycharmProjects\homeCourse2\FLASK\lib\site-packages\jinja2\environment.py", line 936, in handle_exception
    raise rewrite_traceback_stack(source=source)
  File "C:\Users\Павел\PycharmProjects\homeCourse2\app\main\templates\index.html", line 63, in template
    {% endfor %}
jinja2.exceptions.TemplateSyntaxError: Encountered unknown tag 'endfor'.
INFO:werkzeug:127.0.0.1 - - [17/Jul/2022 15:17:36] "[35m[1mGET / HTTP/1.1[0m" 500 -
127.0.0.1 - - [17/Jul/2022 15:17:36] "[35m[1mGET / HTTP/1.1[0m" 500 -
INFO:werkzeug: * Running on http://127.0.0.1:5000 (Press CTRL+C to quit)
 * Running on http://127.0.0.1:5000 (Press CTRL+C to quit)
INFO:werkzeug:127.0.0.1 - - [17/Jul/2022 15:18:08] "GET / HTTP/1.1" 200 -
127.0.0.1 - - [17/Jul/2022 15:18:08] "GET / HTTP/1.1" 200 -
INFO:werkzeug:127.0.0.1 - - [17/Jul/2022 15:18:24] "GET / HTTP/1.1" 200 -
127.0.0.1 - - [17/Jul/2022 15:18:24] "GET / HTTP/1.1" 200 -
INFO:werkzeug:127.0.0.1 - - [17/Jul/2022 15:18:25] "[36mGET /static/styles.min.css HTTP/1.1[0m" 304 -
127.0.0.1 - - [17/Jul/2022 15:18:25] "[36mGET /static/styles.min.css HTTP/1.1[0m" 304 -
INFO:werkzeug:127.0.0.1 - - [17/Jul/2022 15:18:27] "GET /users/leo HTTP/1.1" 200 -
127.0.0.1 - - [17/Jul/2022 15:18:27] "GET /users/leo HTTP/1.1" 200 -
INFO:werkzeug:127.0.0.1 - - [17/Jul/2022 15:18:27] "[36mGET /static/styles.min.css HTTP/1.1[0m" 304 -
127.0.0.1 - - [17/Jul/2022 15:18:27] "[36mGET /static/styles.min.css HTTP/1.1[0m" 304 -
INFO:werkzeug:127.0.0.1 - - [17/Jul/2022 15:18:30] "GET /users/leo HTTP/1.1" 200 -
127.0.0.1 - - [17/Jul/2022 15:18:30] "GET /users/leo HTTP/1.1" 200 -
INFO:werkzeug:127.0.0.1 - - [17/Jul/2022 15:18:30] "[36mGET /static/styles.min.css HTTP/1.1[0m" 304 -
127.0.0.1 - - [17/Jul/2022 15:18:30] "[36mGET /static/styles.min.css HTTP/1.1[0m" 304 -
INFO:werkzeug:127.0.0.1 - - [17/Jul/2022 15:18:31] "GET / HTTP/1.1" 200 -
127.0.0.1 - - [17/Jul/2022 15:18:31] "GET / HTTP/1.1" 200 -
INFO:werkzeug:127.0.0.1 - - [17/Jul/2022 15:18:31] "[36mGET /static/styles.min.css HTTP/1.1[0m" 304 -
127.0.0.1 - - [17/Jul/2022 15:18:31] "[36mGET /static/styles.min.css HTTP/1.1[0m" 304 -
INFO:werkzeug:127.0.0.1 - - [17/Jul/2022 15:18:34] "GET /users/leo HTTP/1.1" 200 -
127.0.0.1 - - [17/Jul/2022 15:18:34] "GET /users/leo HTTP/1.1" 200 -
INFO:werkzeug:127.0.0.1 - - [17/Jul/2022 15:18:34] "[36mGET /static/styles.min.css HTTP/1.1[0m" 304 -
127.0.0.1 - - [17/Jul/2022 15:18:34] "[36mGET /static/styles.min.css HTTP/1.1[0m" 304 -
INFO:werkzeug:127.0.0.1 - - [17/Jul/2022 15:18:36] "GET / HTTP/1.1" 200 -
127.0.0.1 - - [17/Jul/2022 15:18:36] "GET / HTTP/1.1" 200 -
INFO:werkzeug:127.0.0.1 - - [17/Jul/2022 15:18:37] "[36mGET /static/styles.min.css HTTP/1.1[0m" 304 -
127.0.0.1 - - [17/Jul/2022 15:18:37] "[36mGET /static/styles.min.css HTTP/1.1[0m" 304 -
INFO:werkzeug:127.0.0.1 - - [17/Jul/2022 15:18:39] "GET /search HTTP/1.1" 200 -
127.0.0.1 - - [17/Jul/2022 15:18:39] "GET /search HTTP/1.1" 200 -
INFO:werkzeug:127.0.0.1 - - [17/Jul/2022 15:18:39] "[36mGET /static/styles.min.css HTTP/1.1[0m" 304 -
127.0.0.1 - - [17/Jul/2022 15:18:39] "[36mGET /static/styles.min.css HTTP/1.1[0m" 304 -
INFO:werkzeug:127.0.0.1 - - [17/Jul/2022 15:18:43] "GET /search?s=е HTTP/1.1" 200 -
127.0.0.1 - - [17/Jul/2022 15:18:43] "GET /search?s=е HTTP/1.1" 200 -
INFO:werkzeug:127.0.0.1 - - [17/Jul/2022 15:18:44] "[36mGET /static/styles.min.css HTTP/1.1[0m" 304 -
127.0.0.1 - - [17/Jul/2022 15:18:44] "[36mGET /static/styles.min.css HTTP/1.1[0m" 304 -
INFO:werkzeug: * Running on http://127.0.0.1:5000 (Press CTRL+C to quit)
 * Running on http://127.0.0.1:5000 (Press CTRL+C to quit)
ERROR:app.run:Exception on / [GET]
Traceback (most recent call last):
  File "C:\Users\Павел\PycharmProjects\homeCourse2\app\post\dao\post_dao.py", line 18, in load_data
    with open(self.path, "r", encoding="utf-8") as f:
FileNotFoundError: [Errno 2] No such file or directory: '../../data/data.json'

During handling of the above exception, another exception occurred:

Traceback (most recent call last):
  File "C:\Users\Павел\PycharmProjects\homeCourse2\FLASK\lib\site-packages\flask\app.py", line 2077, in wsgi_app
    response = self.full_dispatch_request()
  File "C:\Users\Павел\PycharmProjects\homeCourse2\FLASK\lib\site-packages\flask\app.py", line 1525, in full_dispatch_request
    rv = self.handle_user_exception(e)
  File "C:\Users\Павел\PycharmProjects\homeCourse2\FLASK\lib\site-packages\flask\app.py", line 1523, in full_dispatch_request
    rv = self.dispatch_request()
  File "C:\Users\Павел\PycharmProjects\homeCourse2\FLASK\lib\site-packages\flask\app.py", line 1509, in dispatch_request
    return self.ensure_sync(self.view_functions[rule.endpoint])(**req.view_args)
  File "C:\Users\Павел\PycharmProjects\homeCourse2\app\main\views.py", line 9, in page_index
    post = posts.load_data()
  File "C:\Users\Павел\PycharmProjects\homeCourse2\app\post\dao\post_dao.py", line 21, in load_data
    raise DataSourceError(f"Не удается получить данные из файла{self.path}")
exceptions.data_exceptions.DataSourceError: Не удается получить данные из файла../../data/data.json
Exception on / [GET]
Traceback (most recent call last):
  File "C:\Users\Павел\PycharmProjects\homeCourse2\app\post\dao\post_dao.py", line 18, in load_data
    with open(self.path, "r", encoding="utf-8") as f:
FileNotFoundError: [Errno 2] No such file or directory: '../../data/data.json'

During handling of the above exception, another exception occurred:

Traceback (most recent call last):
  File "C:\Users\Павел\PycharmProjects\homeCourse2\FLASK\lib\site-packages\flask\app.py", line 2077, in wsgi_app
    response = self.full_dispatch_request()
  File "C:\Users\Павел\PycharmProjects\homeCourse2\FLASK\lib\site-packages\flask\app.py", line 1525, in full_dispatch_request
    rv = self.handle_user_exception(e)
  File "C:\Users\Павел\PycharmProjects\homeCourse2\FLASK\lib\site-packages\flask\app.py", line 1523, in full_dispatch_request
    rv = self.dispatch_request()
  File "C:\Users\Павел\PycharmProjects\homeCourse2\FLASK\lib\site-packages\flask\app.py", line 1509, in dispatch_request
    return self.ensure_sync(self.view_functions[rule.endpoint])(**req.view_args)
  File "C:\Users\Павел\PycharmProjects\homeCourse2\app\main\views.py", line 9, in page_index
    post = posts.load_data()
  File "C:\Users\Павел\PycharmProjects\homeCourse2\app\post\dao\post_dao.py", line 21, in load_data
    raise DataSourceError(f"Не удается получить данные из файла{self.path}")
exceptions.data_exceptions.DataSourceError: Не удается получить данные из файла../../data/data.json
INFO:werkzeug:127.0.0.1 - - [17/Jul/2022 15:30:13] "[35m[1mGET / HTTP/1.1[0m" 500 -
127.0.0.1 - - [17/Jul/2022 15:30:13] "[35m[1mGET / HTTP/1.1[0m" 500 -
ERROR:app.run:Exception on / [GET]
Traceback (most recent call last):
  File "C:\Users\Павел\PycharmProjects\homeCourse2\app\post\dao\post_dao.py", line 18, in load_data
    with open(self.path, "r", encoding="utf-8") as f:
FileNotFoundError: [Errno 2] No such file or directory: '../../data/data.json'

During handling of the above exception, another exception occurred:

Traceback (most recent call last):
  File "C:\Users\Павел\PycharmProjects\homeCourse2\FLASK\lib\site-packages\flask\app.py", line 2077, in wsgi_app
    response = self.full_dispatch_request()
  File "C:\Users\Павел\PycharmProjects\homeCourse2\FLASK\lib\site-packages\flask\app.py", line 1525, in full_dispatch_request
    rv = self.handle_user_exception(e)
  File "C:\Users\Павел\PycharmProjects\homeCourse2\FLASK\lib\site-packages\flask\app.py", line 1523, in full_dispatch_request
    rv = self.dispatch_request()
  File "C:\Users\Павел\PycharmProjects\homeCourse2\FLASK\lib\site-packages\flask\app.py", line 1509, in dispatch_request
    return self.ensure_sync(self.view_functions[rule.endpoint])(**req.view_args)
  File "C:\Users\Павел\PycharmProjects\homeCourse2\app\main\views.py", line 9, in page_index
    post = posts.load_data()
  File "C:\Users\Павел\PycharmProjects\homeCourse2\app\post\dao\post_dao.py", line 21, in load_data
    raise DataSourceError(f"Не удается получить данные из файла{self.path}")
exceptions.data_exceptions.DataSourceError: Не удается получить данные из файла../../data/data.json
Exception on / [GET]
Traceback (most recent call last):
  File "C:\Users\Павел\PycharmProjects\homeCourse2\app\post\dao\post_dao.py", line 18, in load_data
    with open(self.path, "r", encoding="utf-8") as f:
FileNotFoundError: [Errno 2] No such file or directory: '../../data/data.json'

During handling of the above exception, another exception occurred:

Traceback (most recent call last):
  File "C:\Users\Павел\PycharmProjects\homeCourse2\FLASK\lib\site-packages\flask\app.py", line 2077, in wsgi_app
    response = self.full_dispatch_request()
  File "C:\Users\Павел\PycharmProjects\homeCourse2\FLASK\lib\site-packages\flask\app.py", line 1525, in full_dispatch_request
    rv = self.handle_user_exception(e)
  File "C:\Users\Павел\PycharmProjects\homeCourse2\FLASK\lib\site-packages\flask\app.py", line 1523, in full_dispatch_request
    rv = self.dispatch_request()
  File "C:\Users\Павел\PycharmProjects\homeCourse2\FLASK\lib\site-packages\flask\app.py", line 1509, in dispatch_request
    return self.ensure_sync(self.view_functions[rule.endpoint])(**req.view_args)
  File "C:\Users\Павел\PycharmProjects\homeCourse2\app\main\views.py", line 9, in page_index
    post = posts.load_data()
  File "C:\Users\Павел\PycharmProjects\homeCourse2\app\post\dao\post_dao.py", line 21, in load_data
    raise DataSourceError(f"Не удается получить данные из файла{self.path}")
exceptions.data_exceptions.DataSourceError: Не удается получить данные из файла../../data/data.json
INFO:werkzeug:127.0.0.1 - - [17/Jul/2022 15:30:15] "[35m[1mGET / HTTP/1.1[0m" 500 -
127.0.0.1 - - [17/Jul/2022 15:30:15] "[35m[1mGET / HTTP/1.1[0m" 500 -
ERROR:app.run:Exception on / [GET]
Traceback (most recent call last):
  File "C:\Users\Павел\PycharmProjects\homeCourse2\app\post\dao\post_dao.py", line 18, in load_data
    with open(self.path, "r", encoding="utf-8") as f:
FileNotFoundError: [Errno 2] No such file or directory: '../../data/data.json'

During handling of the above exception, another exception occurred:

Traceback (most recent call last):
  File "C:\Users\Павел\PycharmProjects\homeCourse2\FLASK\lib\site-packages\flask\app.py", line 2077, in wsgi_app
    response = self.full_dispatch_request()
  File "C:\Users\Павел\PycharmProjects\homeCourse2\FLASK\lib\site-packages\flask\app.py", line 1525, in full_dispatch_request
    rv = self.handle_user_exception(e)
  File "C:\Users\Павел\PycharmProjects\homeCourse2\FLASK\lib\site-packages\flask\app.py", line 1523, in full_dispatch_request
    rv = self.dispatch_request()
  File "C:\Users\Павел\PycharmProjects\homeCourse2\FLASK\lib\site-packages\flask\app.py", line 1509, in dispatch_request
    return self.ensure_sync(self.view_functions[rule.endpoint])(**req.view_args)
  File "C:\Users\Павел\PycharmProjects\homeCourse2\app\main\views.py", line 9, in page_index
    post = posts.load_data()
  File "C:\Users\Павел\PycharmProjects\homeCourse2\app\post\dao\post_dao.py", line 21, in load_data
    raise DataSourceError(f"Не удается получить данные из файла{self.path}")
exceptions.data_exceptions.DataSourceError: Не удается получить данные из файла../../data/data.json
Exception on / [GET]
Traceback (most recent call last):
  File "C:\Users\Павел\PycharmProjects\homeCourse2\app\post\dao\post_dao.py", line 18, in load_data
    with open(self.path, "r", encoding="utf-8") as f:
FileNotFoundError: [Errno 2] No such file or directory: '../../data/data.json'

During handling of the above exception, another exception occurred:

Traceback (most recent call last):
  File "C:\Users\Павел\PycharmProjects\homeCourse2\FLASK\lib\site-packages\flask\app.py", line 2077, in wsgi_app
    response = self.full_dispatch_request()
  File "C:\Users\Павел\PycharmProjects\homeCourse2\FLASK\lib\site-packages\flask\app.py", line 1525, in full_dispatch_request
    rv = self.handle_user_exception(e)
  File "C:\Users\Павел\PycharmProjects\homeCourse2\FLASK\lib\site-packages\flask\app.py", line 1523, in full_dispatch_request
    rv = self.dispatch_request()
  File "C:\Users\Павел\PycharmProjects\homeCourse2\FLASK\lib\site-packages\flask\app.py", line 1509, in dispatch_request
    return self.ensure_sync(self.view_functions[rule.endpoint])(**req.view_args)
  File "C:\Users\Павел\PycharmProjects\homeCourse2\app\main\views.py", line 9, in page_index
    post = posts.load_data()
  File "C:\Users\Павел\PycharmProjects\homeCourse2\app\post\dao\post_dao.py", line 21, in load_data
    raise DataSourceError(f"Не удается получить данные из файла{self.path}")
exceptions.data_exceptions.DataSourceError: Не удается получить данные из файла../../data/data.json
INFO:werkzeug:127.0.0.1 - - [17/Jul/2022 15:30:16] "[35m[1mGET / HTTP/1.1[0m" 500 -
127.0.0.1 - - [17/Jul/2022 15:30:16] "[35m[1mGET / HTTP/1.1[0m" 500 -
INFO:werkzeug: * Running on http://127.0.0.1:5000 (Press CTRL+C to quit)
 * Running on http://127.0.0.1:5000 (Press CTRL+C to quit)
ERROR:app.run:Exception on / [GET]
Traceback (most recent call last):
  File "C:\Users\Павел\PycharmProjects\homeCourse2\app\post\dao\post_dao.py", line 18, in load_data
    with open(self.path, "r", encoding="utf-8") as f:
FileNotFoundError: [Errno 2] No such file or directory: '../../data/data.json'

During handling of the above exception, another exception occurred:

Traceback (most recent call last):
  File "C:\Users\Павел\PycharmProjects\homeCourse2\FLASK\lib\site-packages\flask\app.py", line 2077, in wsgi_app
    response = self.full_dispatch_request()
  File "C:\Users\Павел\PycharmProjects\homeCourse2\FLASK\lib\site-packages\flask\app.py", line 1525, in full_dispatch_request
    rv = self.handle_user_exception(e)
  File "C:\Users\Павел\PycharmProjects\homeCourse2\FLASK\lib\site-packages\flask\app.py", line 1523, in full_dispatch_request
    rv = self.dispatch_request()
  File "C:\Users\Павел\PycharmProjects\homeCourse2\FLASK\lib\site-packages\flask\app.py", line 1509, in dispatch_request
    return self.ensure_sync(self.view_functions[rule.endpoint])(**req.view_args)
  File "C:\Users\Павел\PycharmProjects\homeCourse2\app\main\views.py", line 9, in page_index
    post = posts.load_data()
  File "C:\Users\Павел\PycharmProjects\homeCourse2\app\post\dao\post_dao.py", line 21, in load_data
    raise DataSourceError(f"Не удается получить данные из файла{self.path}")
exceptions.data_exceptions.DataSourceError: Не удается получить данные из файла../../data/data.json
Exception on / [GET]
Traceback (most recent call last):
  File "C:\Users\Павел\PycharmProjects\homeCourse2\app\post\dao\post_dao.py", line 18, in load_data
    with open(self.path, "r", encoding="utf-8") as f:
FileNotFoundError: [Errno 2] No such file or directory: '../../data/data.json'

During handling of the above exception, another exception occurred:

Traceback (most recent call last):
  File "C:\Users\Павел\PycharmProjects\homeCourse2\FLASK\lib\site-packages\flask\app.py", line 2077, in wsgi_app
    response = self.full_dispatch_request()
  File "C:\Users\Павел\PycharmProjects\homeCourse2\FLASK\lib\site-packages\flask\app.py", line 1525, in full_dispatch_request
    rv = self.handle_user_exception(e)
  File "C:\Users\Павел\PycharmProjects\homeCourse2\FLASK\lib\site-packages\flask\app.py", line 1523, in full_dispatch_request
    rv = self.dispatch_request()
  File "C:\Users\Павел\PycharmProjects\homeCourse2\FLASK\lib\site-packages\flask\app.py", line 1509, in dispatch_request
    return self.ensure_sync(self.view_functions[rule.endpoint])(**req.view_args)
  File "C:\Users\Павел\PycharmProjects\homeCourse2\app\main\views.py", line 9, in page_index
    post = posts.load_data()
  File "C:\Users\Павел\PycharmProjects\homeCourse2\app\post\dao\post_dao.py", line 21, in load_data
    raise DataSourceError(f"Не удается получить данные из файла{self.path}")
exceptions.data_exceptions.DataSourceError: Не удается получить данные из файла../../data/data.json
INFO:werkzeug:127.0.0.1 - - [17/Jul/2022 15:30:41] "[35m[1mGET / HTTP/1.1[0m" 500 -
127.0.0.1 - - [17/Jul/2022 15:30:41] "[35m[1mGET / HTTP/1.1[0m" 500 -
ERROR:app.run:Exception on / [GET]
Traceback (most recent call last):
  File "C:\Users\Павел\PycharmProjects\homeCourse2\app\post\dao\post_dao.py", line 18, in load_data
    with open(self.path, "r", encoding="utf-8") as f:
FileNotFoundError: [Errno 2] No such file or directory: '../../data/data.json'

During handling of the above exception, another exception occurred:

Traceback (most recent call last):
  File "C:\Users\Павел\PycharmProjects\homeCourse2\FLASK\lib\site-packages\flask\app.py", line 2077, in wsgi_app
    response = self.full_dispatch_request()
  File "C:\Users\Павел\PycharmProjects\homeCourse2\FLASK\lib\site-packages\flask\app.py", line 1525, in full_dispatch_request
    rv = self.handle_user_exception(e)
  File "C:\Users\Павел\PycharmProjects\homeCourse2\FLASK\lib\site-packages\flask\app.py", line 1523, in full_dispatch_request
    rv = self.dispatch_request()
  File "C:\Users\Павел\PycharmProjects\homeCourse2\FLASK\lib\site-packages\flask\app.py", line 1509, in dispatch_request
    return self.ensure_sync(self.view_functions[rule.endpoint])(**req.view_args)
  File "C:\Users\Павел\PycharmProjects\homeCourse2\app\main\views.py", line 9, in page_index
    post = posts.load_data()
  File "C:\Users\Павел\PycharmProjects\homeCourse2\app\post\dao\post_dao.py", line 21, in load_data
    raise DataSourceError(f"Не удается получить данные из файла{self.path}")
exceptions.data_exceptions.DataSourceError: Не удается получить данные из файла../../data/data.json
Exception on / [GET]
Traceback (most recent call last):
  File "C:\Users\Павел\PycharmProjects\homeCourse2\app\post\dao\post_dao.py", line 18, in load_data
    with open(self.path, "r", encoding="utf-8") as f:
FileNotFoundError: [Errno 2] No such file or directory: '../../data/data.json'

During handling of the above exception, another exception occurred:

Traceback (most recent call last):
  File "C:\Users\Павел\PycharmProjects\homeCourse2\FLASK\lib\site-packages\flask\app.py", line 2077, in wsgi_app
    response = self.full_dispatch_request()
  File "C:\Users\Павел\PycharmProjects\homeCourse2\FLASK\lib\site-packages\flask\app.py", line 1525, in full_dispatch_request
    rv = self.handle_user_exception(e)
  File "C:\Users\Павел\PycharmProjects\homeCourse2\FLASK\lib\site-packages\flask\app.py", line 1523, in full_dispatch_request
    rv = self.dispatch_request()
  File "C:\Users\Павел\PycharmProjects\homeCourse2\FLASK\lib\site-packages\flask\app.py", line 1509, in dispatch_request
    return self.ensure_sync(self.view_functions[rule.endpoint])(**req.view_args)
  File "C:\Users\Павел\PycharmProjects\homeCourse2\app\main\views.py", line 9, in page_index
    post = posts.load_data()
  File "C:\Users\Павел\PycharmProjects\homeCourse2\app\post\dao\post_dao.py", line 21, in load_data
    raise DataSourceError(f"Не удается получить данные из файла{self.path}")
exceptions.data_exceptions.DataSourceError: Не удается получить данные из файла../../data/data.json
INFO:werkzeug:127.0.0.1 - - [17/Jul/2022 15:30:44] "[35m[1mGET / HTTP/1.1[0m" 500 -
127.0.0.1 - - [17/Jul/2022 15:30:44] "[35m[1mGET / HTTP/1.1[0m" 500 -
ERROR:app.run:Exception on / [GET]
Traceback (most recent call last):
  File "C:\Users\Павел\PycharmProjects\homeCourse2\app\post\dao\post_dao.py", line 18, in load_data
    with open(self.path, "r", encoding="utf-8") as f:
FileNotFoundError: [Errno 2] No such file or directory: '../../data/data.json'

During handling of the above exception, another exception occurred:

Traceback (most recent call last):
  File "C:\Users\Павел\PycharmProjects\homeCourse2\FLASK\lib\site-packages\flask\app.py", line 2077, in wsgi_app
    response = self.full_dispatch_request()
  File "C:\Users\Павел\PycharmProjects\homeCourse2\FLASK\lib\site-packages\flask\app.py", line 1525, in full_dispatch_request
    rv = self.handle_user_exception(e)
  File "C:\Users\Павел\PycharmProjects\homeCourse2\FLASK\lib\site-packages\flask\app.py", line 1523, in full_dispatch_request
    rv = self.dispatch_request()
  File "C:\Users\Павел\PycharmProjects\homeCourse2\FLASK\lib\site-packages\flask\app.py", line 1509, in dispatch_request
    return self.ensure_sync(self.view_functions[rule.endpoint])(**req.view_args)
  File "C:\Users\Павел\PycharmProjects\homeCourse2\app\main\views.py", line 9, in page_index
    post = posts.load_data()
  File "C:\Users\Павел\PycharmProjects\homeCourse2\app\post\dao\post_dao.py", line 21, in load_data
    raise DataSourceError(f"Не удается получить данные из файла{self.path}")
exceptions.data_exceptions.DataSourceError: Не удается получить данные из файла../../data/data.json
Exception on / [GET]
Traceback (most recent call last):
  File "C:\Users\Павел\PycharmProjects\homeCourse2\app\post\dao\post_dao.py", line 18, in load_data
    with open(self.path, "r", encoding="utf-8") as f:
FileNotFoundError: [Errno 2] No such file or directory: '../../data/data.json'

During handling of the above exception, another exception occurred:

Traceback (most recent call last):
  File "C:\Users\Павел\PycharmProjects\homeCourse2\FLASK\lib\site-packages\flask\app.py", line 2077, in wsgi_app
    response = self.full_dispatch_request()
  File "C:\Users\Павел\PycharmProjects\homeCourse2\FLASK\lib\site-packages\flask\app.py", line 1525, in full_dispatch_request
    rv = self.handle_user_exception(e)
  File "C:\Users\Павел\PycharmProjects\homeCourse2\FLASK\lib\site-packages\flask\app.py", line 1523, in full_dispatch_request
    rv = self.dispatch_request()
  File "C:\Users\Павел\PycharmProjects\homeCourse2\FLASK\lib\site-packages\flask\app.py", line 1509, in dispatch_request
    return self.ensure_sync(self.view_functions[rule.endpoint])(**req.view_args)
  File "C:\Users\Павел\PycharmProjects\homeCourse2\app\main\views.py", line 9, in page_index
    post = posts.load_data()
  File "C:\Users\Павел\PycharmProjects\homeCourse2\app\post\dao\post_dao.py", line 21, in load_data
    raise DataSourceError(f"Не удается получить данные из файла{self.path}")
exceptions.data_exceptions.DataSourceError: Не удается получить данные из файла../../data/data.json
INFO:werkzeug:127.0.0.1 - - [17/Jul/2022 15:30:59] "[35m[1mGET / HTTP/1.1[0m" 500 -
127.0.0.1 - - [17/Jul/2022 15:30:59] "[35m[1mGET / HTTP/1.1[0m" 500 -
INFO:werkzeug: * Running on http://127.0.0.1:5000 (Press CTRL+C to quit)
 * Running on http://127.0.0.1:5000 (Press CTRL+C to quit)
ERROR:app.run:Exception on / [GET]
Traceback (most recent call last):
  File "C:\Users\Павел\PycharmProjects\homeCourse2\app\post\dao\post_dao.py", line 18, in load_data
    with open(self.path, "r", encoding="utf-8") as f:
FileNotFoundError: [Errno 2] No such file or directory: '../../data/data.json'

During handling of the above exception, another exception occurred:

Traceback (most recent call last):
  File "C:\Users\Павел\PycharmProjects\homeCourse2\FLASK\lib\site-packages\flask\app.py", line 2077, in wsgi_app
    response = self.full_dispatch_request()
  File "C:\Users\Павел\PycharmProjects\homeCourse2\FLASK\lib\site-packages\flask\app.py", line 1525, in full_dispatch_request
    rv = self.handle_user_exception(e)
  File "C:\Users\Павел\PycharmProjects\homeCourse2\FLASK\lib\site-packages\flask\app.py", line 1523, in full_dispatch_request
    rv = self.dispatch_request()
  File "C:\Users\Павел\PycharmProjects\homeCourse2\FLASK\lib\site-packages\flask\app.py", line 1509, in dispatch_request
    return self.ensure_sync(self.view_functions[rule.endpoint])(**req.view_args)
  File "C:\Users\Павел\PycharmProjects\homeCourse2\app\main\views.py", line 9, in page_index
    post = posts.load_data()
  File "C:\Users\Павел\PycharmProjects\homeCourse2\app\post\dao\post_dao.py", line 21, in load_data
    raise DataSourceError(f"Не удается получить данные из файла{self.path}")
exceptions.data_exceptions.DataSourceError: Не удается получить данные из файла../../data/data.json
Exception on / [GET]
Traceback (most recent call last):
  File "C:\Users\Павел\PycharmProjects\homeCourse2\app\post\dao\post_dao.py", line 18, in load_data
    with open(self.path, "r", encoding="utf-8") as f:
FileNotFoundError: [Errno 2] No such file or directory: '../../data/data.json'

During handling of the above exception, another exception occurred:

Traceback (most recent call last):
  File "C:\Users\Павел\PycharmProjects\homeCourse2\FLASK\lib\site-packages\flask\app.py", line 2077, in wsgi_app
    response = self.full_dispatch_request()
  File "C:\Users\Павел\PycharmProjects\homeCourse2\FLASK\lib\site-packages\flask\app.py", line 1525, in full_dispatch_request
    rv = self.handle_user_exception(e)
  File "C:\Users\Павел\PycharmProjects\homeCourse2\FLASK\lib\site-packages\flask\app.py", line 1523, in full_dispatch_request
    rv = self.dispatch_request()
  File "C:\Users\Павел\PycharmProjects\homeCourse2\FLASK\lib\site-packages\flask\app.py", line 1509, in dispatch_request
    return self.ensure_sync(self.view_functions[rule.endpoint])(**req.view_args)
  File "C:\Users\Павел\PycharmProjects\homeCourse2\app\main\views.py", line 9, in page_index
    post = posts.load_data()
  File "C:\Users\Павел\PycharmProjects\homeCourse2\app\post\dao\post_dao.py", line 21, in load_data
    raise DataSourceError(f"Не удается получить данные из файла{self.path}")
exceptions.data_exceptions.DataSourceError: Не удается получить данные из файла../../data/data.json
INFO:werkzeug:127.0.0.1 - - [17/Jul/2022 15:31:58] "[35m[1mGET / HTTP/1.1[0m" 500 -
127.0.0.1 - - [17/Jul/2022 15:31:58] "[35m[1mGET / HTTP/1.1[0m" 500 -
ERROR:app.run:Exception on / [GET]
Traceback (most recent call last):
  File "C:\Users\Павел\PycharmProjects\homeCourse2\app\post\dao\post_dao.py", line 18, in load_data
    with open(self.path, "r", encoding="utf-8") as f:
FileNotFoundError: [Errno 2] No such file or directory: '../../data/data.json'

During handling of the above exception, another exception occurred:

Traceback (most recent call last):
  File "C:\Users\Павел\PycharmProjects\homeCourse2\FLASK\lib\site-packages\flask\app.py", line 2077, in wsgi_app
    response = self.full_dispatch_request()
  File "C:\Users\Павел\PycharmProjects\homeCourse2\FLASK\lib\site-packages\flask\app.py", line 1525, in full_dispatch_request
    rv = self.handle_user_exception(e)
  File "C:\Users\Павел\PycharmProjects\homeCourse2\FLASK\lib\site-packages\flask\app.py", line 1523, in full_dispatch_request
    rv = self.dispatch_request()
  File "C:\Users\Павел\PycharmProjects\homeCourse2\FLASK\lib\site-packages\flask\app.py", line 1509, in dispatch_request
    return self.ensure_sync(self.view_functions[rule.endpoint])(**req.view_args)
  File "C:\Users\Павел\PycharmProjects\homeCourse2\app\main\views.py", line 9, in page_index
    post = posts.load_data()
  File "C:\Users\Павел\PycharmProjects\homeCourse2\app\post\dao\post_dao.py", line 21, in load_data
    raise DataSourceError(f"Не удается получить данные из файла{self.path}")
exceptions.data_exceptions.DataSourceError: Не удается получить данные из файла../../data/data.json
Exception on / [GET]
Traceback (most recent call last):
  File "C:\Users\Павел\PycharmProjects\homeCourse2\app\post\dao\post_dao.py", line 18, in load_data
    with open(self.path, "r", encoding="utf-8") as f:
FileNotFoundError: [Errno 2] No such file or directory: '../../data/data.json'

During handling of the above exception, another exception occurred:

Traceback (most recent call last):
  File "C:\Users\Павел\PycharmProjects\homeCourse2\FLASK\lib\site-packages\flask\app.py", line 2077, in wsgi_app
    response = self.full_dispatch_request()
  File "C:\Users\Павел\PycharmProjects\homeCourse2\FLASK\lib\site-packages\flask\app.py", line 1525, in full_dispatch_request
    rv = self.handle_user_exception(e)
  File "C:\Users\Павел\PycharmProjects\homeCourse2\FLASK\lib\site-packages\flask\app.py", line 1523, in full_dispatch_request
    rv = self.dispatch_request()
  File "C:\Users\Павел\PycharmProjects\homeCourse2\FLASK\lib\site-packages\flask\app.py", line 1509, in dispatch_request
    return self.ensure_sync(self.view_functions[rule.endpoint])(**req.view_args)
  File "C:\Users\Павел\PycharmProjects\homeCourse2\app\main\views.py", line 9, in page_index
    post = posts.load_data()
  File "C:\Users\Павел\PycharmProjects\homeCourse2\app\post\dao\post_dao.py", line 21, in load_data
    raise DataSourceError(f"Не удается получить данные из файла{self.path}")
exceptions.data_exceptions.DataSourceError: Не удается получить данные из файла../../data/data.json
INFO:werkzeug:127.0.0.1 - - [17/Jul/2022 15:31:59] "[35m[1mGET / HTTP/1.1[0m" 500 -
127.0.0.1 - - [17/Jul/2022 15:31:59] "[35m[1mGET / HTTP/1.1[0m" 500 -
ERROR:app.run:Exception on / [GET]
Traceback (most recent call last):
  File "C:\Users\Павел\PycharmProjects\homeCourse2\app\post\dao\post_dao.py", line 18, in load_data
    with open(self.path, "r", encoding="utf-8") as f:
FileNotFoundError: [Errno 2] No such file or directory: '../../data/data.json'

During handling of the above exception, another exception occurred:

Traceback (most recent call last):
  File "C:\Users\Павел\PycharmProjects\homeCourse2\FLASK\lib\site-packages\flask\app.py", line 2077, in wsgi_app
    response = self.full_dispatch_request()
  File "C:\Users\Павел\PycharmProjects\homeCourse2\FLASK\lib\site-packages\flask\app.py", line 1525, in full_dispatch_request
    rv = self.handle_user_exception(e)
  File "C:\Users\Павел\PycharmProjects\homeCourse2\FLASK\lib\site-packages\flask\app.py", line 1523, in full_dispatch_request
    rv = self.dispatch_request()
  File "C:\Users\Павел\PycharmProjects\homeCourse2\FLASK\lib\site-packages\flask\app.py", line 1509, in dispatch_request
    return self.ensure_sync(self.view_functions[rule.endpoint])(**req.view_args)
  File "C:\Users\Павел\PycharmProjects\homeCourse2\app\main\views.py", line 9, in page_index
    post = posts.load_data()
  File "C:\Users\Павел\PycharmProjects\homeCourse2\app\post\dao\post_dao.py", line 21, in load_data
    raise DataSourceError(f"Не удается получить данные из файла{self.path}")
exceptions.data_exceptions.DataSourceError: Не удается получить данные из файла../../data/data.json
Exception on / [GET]
Traceback (most recent call last):
  File "C:\Users\Павел\PycharmProjects\homeCourse2\app\post\dao\post_dao.py", line 18, in load_data
    with open(self.path, "r", encoding="utf-8") as f:
FileNotFoundError: [Errno 2] No such file or directory: '../../data/data.json'

During handling of the above exception, another exception occurred:

Traceback (most recent call last):
  File "C:\Users\Павел\PycharmProjects\homeCourse2\FLASK\lib\site-packages\flask\app.py", line 2077, in wsgi_app
    response = self.full_dispatch_request()
  File "C:\Users\Павел\PycharmProjects\homeCourse2\FLASK\lib\site-packages\flask\app.py", line 1525, in full_dispatch_request
    rv = self.handle_user_exception(e)
  File "C:\Users\Павел\PycharmProjects\homeCourse2\FLASK\lib\site-packages\flask\app.py", line 1523, in full_dispatch_request
    rv = self.dispatch_request()
  File "C:\Users\Павел\PycharmProjects\homeCourse2\FLASK\lib\site-packages\flask\app.py", line 1509, in dispatch_request
    return self.ensure_sync(self.view_functions[rule.endpoint])(**req.view_args)
  File "C:\Users\Павел\PycharmProjects\homeCourse2\app\main\views.py", line 9, in page_index
    post = posts.load_data()
  File "C:\Users\Павел\PycharmProjects\homeCourse2\app\post\dao\post_dao.py", line 21, in load_data
    raise DataSourceError(f"Не удается получить данные из файла{self.path}")
exceptions.data_exceptions.DataSourceError: Не удается получить данные из файла../../data/data.json
INFO:werkzeug:127.0.0.1 - - [17/Jul/2022 15:32:00] "[35m[1mGET / HTTP/1.1[0m" 500 -
127.0.0.1 - - [17/Jul/2022 15:32:00] "[35m[1mGET / HTTP/1.1[0m" 500 -
ERROR:app.run:Exception on / [GET]
Traceback (most recent call last):
  File "C:\Users\Павел\PycharmProjects\homeCourse2\app\post\dao\post_dao.py", line 18, in load_data
    with open(self.path, "r", encoding="utf-8") as f:
FileNotFoundError: [Errno 2] No such file or directory: '../../data/data.json'

During handling of the above exception, another exception occurred:

Traceback (most recent call last):
  File "C:\Users\Павел\PycharmProjects\homeCourse2\FLASK\lib\site-packages\flask\app.py", line 2077, in wsgi_app
    response = self.full_dispatch_request()
  File "C:\Users\Павел\PycharmProjects\homeCourse2\FLASK\lib\site-packages\flask\app.py", line 1525, in full_dispatch_request
    rv = self.handle_user_exception(e)
  File "C:\Users\Павел\PycharmProjects\homeCourse2\FLASK\lib\site-packages\flask\app.py", line 1523, in full_dispatch_request
    rv = self.dispatch_request()
  File "C:\Users\Павел\PycharmProjects\homeCourse2\FLASK\lib\site-packages\flask\app.py", line 1509, in dispatch_request
    return self.ensure_sync(self.view_functions[rule.endpoint])(**req.view_args)
  File "C:\Users\Павел\PycharmProjects\homeCourse2\app\main\views.py", line 9, in page_index
    post = posts.load_data()
  File "C:\Users\Павел\PycharmProjects\homeCourse2\app\post\dao\post_dao.py", line 21, in load_data
    raise DataSourceError(f"Не удается получить данные из файла{self.path}")
exceptions.data_exceptions.DataSourceError: Не удается получить данные из файла../../data/data.json
Exception on / [GET]
Traceback (most recent call last):
  File "C:\Users\Павел\PycharmProjects\homeCourse2\app\post\dao\post_dao.py", line 18, in load_data
    with open(self.path, "r", encoding="utf-8") as f:
FileNotFoundError: [Errno 2] No such file or directory: '../../data/data.json'

During handling of the above exception, another exception occurred:

Traceback (most recent call last):
  File "C:\Users\Павел\PycharmProjects\homeCourse2\FLASK\lib\site-packages\flask\app.py", line 2077, in wsgi_app
    response = self.full_dispatch_request()
  File "C:\Users\Павел\PycharmProjects\homeCourse2\FLASK\lib\site-packages\flask\app.py", line 1525, in full_dispatch_request
    rv = self.handle_user_exception(e)
  File "C:\Users\Павел\PycharmProjects\homeCourse2\FLASK\lib\site-packages\flask\app.py", line 1523, in full_dispatch_request
    rv = self.dispatch_request()
  File "C:\Users\Павел\PycharmProjects\homeCourse2\FLASK\lib\site-packages\flask\app.py", line 1509, in dispatch_request
    return self.ensure_sync(self.view_functions[rule.endpoint])(**req.view_args)
  File "C:\Users\Павел\PycharmProjects\homeCourse2\app\main\views.py", line 9, in page_index
    post = posts.load_data()
  File "C:\Users\Павел\PycharmProjects\homeCourse2\app\post\dao\post_dao.py", line 21, in load_data
    raise DataSourceError(f"Не удается получить данные из файла{self.path}")
exceptions.data_exceptions.DataSourceError: Не удается получить данные из файла../../data/data.json
INFO:werkzeug:127.0.0.1 - - [17/Jul/2022 15:32:00] "[35m[1mGET / HTTP/1.1[0m" 500 -
127.0.0.1 - - [17/Jul/2022 15:32:00] "[35m[1mGET / HTTP/1.1[0m" 500 -
ERROR:app.run:Exception on / [GET]
Traceback (most recent call last):
  File "C:\Users\Павел\PycharmProjects\homeCourse2\app\post\dao\post_dao.py", line 18, in load_data
    with open(self.path, "r", encoding="utf-8") as f:
FileNotFoundError: [Errno 2] No such file or directory: '../../data/data.json'

During handling of the above exception, another exception occurred:

Traceback (most recent call last):
  File "C:\Users\Павел\PycharmProjects\homeCourse2\FLASK\lib\site-packages\flask\app.py", line 2077, in wsgi_app
    response = self.full_dispatch_request()
  File "C:\Users\Павел\PycharmProjects\homeCourse2\FLASK\lib\site-packages\flask\app.py", line 1525, in full_dispatch_request
    rv = self.handle_user_exception(e)
  File "C:\Users\Павел\PycharmProjects\homeCourse2\FLASK\lib\site-packages\flask\app.py", line 1523, in full_dispatch_request
    rv = self.dispatch_request()
  File "C:\Users\Павел\PycharmProjects\homeCourse2\FLASK\lib\site-packages\flask\app.py", line 1509, in dispatch_request
    return self.ensure_sync(self.view_functions[rule.endpoint])(**req.view_args)
  File "C:\Users\Павел\PycharmProjects\homeCourse2\app\main\views.py", line 9, in page_index
    post = posts.load_data()
  File "C:\Users\Павел\PycharmProjects\homeCourse2\app\post\dao\post_dao.py", line 21, in load_data
    raise DataSourceError(f"Не удается получить данные из файла{self.path}")
exceptions.data_exceptions.DataSourceError: Не удается получить данные из файла../../data/data.json
Exception on / [GET]
Traceback (most recent call last):
  File "C:\Users\Павел\PycharmProjects\homeCourse2\app\post\dao\post_dao.py", line 18, in load_data
    with open(self.path, "r", encoding="utf-8") as f:
FileNotFoundError: [Errno 2] No such file or directory: '../../data/data.json'

During handling of the above exception, another exception occurred:

Traceback (most recent call last):
  File "C:\Users\Павел\PycharmProjects\homeCourse2\FLASK\lib\site-packages\flask\app.py", line 2077, in wsgi_app
    response = self.full_dispatch_request()
  File "C:\Users\Павел\PycharmProjects\homeCourse2\FLASK\lib\site-packages\flask\app.py", line 1525, in full_dispatch_request
    rv = self.handle_user_exception(e)
  File "C:\Users\Павел\PycharmProjects\homeCourse2\FLASK\lib\site-packages\flask\app.py", line 1523, in full_dispatch_request
    rv = self.dispatch_request()
  File "C:\Users\Павел\PycharmProjects\homeCourse2\FLASK\lib\site-packages\flask\app.py", line 1509, in dispatch_request
    return self.ensure_sync(self.view_functions[rule.endpoint])(**req.view_args)
  File "C:\Users\Павел\PycharmProjects\homeCourse2\app\main\views.py", line 9, in page_index
    post = posts.load_data()
  File "C:\Users\Павел\PycharmProjects\homeCourse2\app\post\dao\post_dao.py", line 21, in load_data
    raise DataSourceError(f"Не удается получить данные из файла{self.path}")
exceptions.data_exceptions.DataSourceError: Не удается получить данные из файла../../data/data.json
INFO:werkzeug:127.0.0.1 - - [17/Jul/2022 15:32:01] "[35m[1mGET / HTTP/1.1[0m" 500 -
127.0.0.1 - - [17/Jul/2022 15:32:01] "[35m[1mGET / HTTP/1.1[0m" 500 -
INFO:werkzeug: * Running on http://127.0.0.1:5000 (Press CTRL+C to quit)
 * Running on http://127.0.0.1:5000 (Press CTRL+C to quit)
ERROR:app.run:Exception on / [GET]
Traceback (most recent call last):
  File "C:\Users\Павел\PycharmProjects\homeCourse2\app\post\dao\post_dao.py", line 18, in load_data
    with open(self.path, "r", encoding="utf-8") as f:
FileNotFoundError: [Errno 2] No such file or directory: '/../../data/data.json'

During handling of the above exception, another exception occurred:

Traceback (most recent call last):
  File "C:\Users\Павел\PycharmProjects\homeCourse2\FLASK\lib\site-packages\flask\app.py", line 2077, in wsgi_app
    response = self.full_dispatch_request()
  File "C:\Users\Павел\PycharmProjects\homeCourse2\FLASK\lib\site-packages\flask\app.py", line 1525, in full_dispatch_request
    rv = self.handle_user_exception(e)
  File "C:\Users\Павел\PycharmProjects\homeCourse2\FLASK\lib\site-packages\flask\app.py", line 1523, in full_dispatch_request
    rv = self.dispatch_request()
  File "C:\Users\Павел\PycharmProjects\homeCourse2\FLASK\lib\site-packages\flask\app.py", line 1509, in dispatch_request
    return self.ensure_sync(self.view_functions[rule.endpoint])(**req.view_args)
  File "C:\Users\Павел\PycharmProjects\homeCourse2\app\main\views.py", line 9, in page_index
    post = posts.load_data()
  File "C:\Users\Павел\PycharmProjects\homeCourse2\app\post\dao\post_dao.py", line 21, in load_data
    raise DataSourceError(f"Не удается получить данные из файла{self.path}")
exceptions.data_exceptions.DataSourceError: Не удается получить данные из файла/../../data/data.json
Exception on / [GET]
Traceback (most recent call last):
  File "C:\Users\Павел\PycharmProjects\homeCourse2\app\post\dao\post_dao.py", line 18, in load_data
    with open(self.path, "r", encoding="utf-8") as f:
FileNotFoundError: [Errno 2] No such file or directory: '/../../data/data.json'

During handling of the above exception, another exception occurred:

Traceback (most recent call last):
  File "C:\Users\Павел\PycharmProjects\homeCourse2\FLASK\lib\site-packages\flask\app.py", line 2077, in wsgi_app
    response = self.full_dispatch_request()
  File "C:\Users\Павел\PycharmProjects\homeCourse2\FLASK\lib\site-packages\flask\app.py", line 1525, in full_dispatch_request
    rv = self.handle_user_exception(e)
  File "C:\Users\Павел\PycharmProjects\homeCourse2\FLASK\lib\site-packages\flask\app.py", line 1523, in full_dispatch_request
    rv = self.dispatch_request()
  File "C:\Users\Павел\PycharmProjects\homeCourse2\FLASK\lib\site-packages\flask\app.py", line 1509, in dispatch_request
    return self.ensure_sync(self.view_functions[rule.endpoint])(**req.view_args)
  File "C:\Users\Павел\PycharmProjects\homeCourse2\app\main\views.py", line 9, in page_index
    post = posts.load_data()
  File "C:\Users\Павел\PycharmProjects\homeCourse2\app\post\dao\post_dao.py", line 21, in load_data
    raise DataSourceError(f"Не удается получить данные из файла{self.path}")
exceptions.data_exceptions.DataSourceError: Не удается получить данные из файла/../../data/data.json
INFO:werkzeug:127.0.0.1 - - [17/Jul/2022 15:32:11] "[35m[1mGET / HTTP/1.1[0m" 500 -
127.0.0.1 - - [17/Jul/2022 15:32:11] "[35m[1mGET / HTTP/1.1[0m" 500 -
ERROR:app.run:Exception on / [GET]
Traceback (most recent call last):
  File "C:\Users\Павел\PycharmProjects\homeCourse2\app\post\dao\post_dao.py", line 18, in load_data
    with open(self.path, "r", encoding="utf-8") as f:
FileNotFoundError: [Errno 2] No such file or directory: '/../../data/data.json'

During handling of the above exception, another exception occurred:

Traceback (most recent call last):
  File "C:\Users\Павел\PycharmProjects\homeCourse2\FLASK\lib\site-packages\flask\app.py", line 2077, in wsgi_app
    response = self.full_dispatch_request()
  File "C:\Users\Павел\PycharmProjects\homeCourse2\FLASK\lib\site-packages\flask\app.py", line 1525, in full_dispatch_request
    rv = self.handle_user_exception(e)
  File "C:\Users\Павел\PycharmProjects\homeCourse2\FLASK\lib\site-packages\flask\app.py", line 1523, in full_dispatch_request
    rv = self.dispatch_request()
  File "C:\Users\Павел\PycharmProjects\homeCourse2\FLASK\lib\site-packages\flask\app.py", line 1509, in dispatch_request
    return self.ensure_sync(self.view_functions[rule.endpoint])(**req.view_args)
  File "C:\Users\Павел\PycharmProjects\homeCourse2\app\main\views.py", line 9, in page_index
    post = posts.load_data()
  File "C:\Users\Павел\PycharmProjects\homeCourse2\app\post\dao\post_dao.py", line 21, in load_data
    raise DataSourceError(f"Не удается получить данные из файла{self.path}")
exceptions.data_exceptions.DataSourceError: Не удается получить данные из файла/../../data/data.json
Exception on / [GET]
Traceback (most recent call last):
  File "C:\Users\Павел\PycharmProjects\homeCourse2\app\post\dao\post_dao.py", line 18, in load_data
    with open(self.path, "r", encoding="utf-8") as f:
FileNotFoundError: [Errno 2] No such file or directory: '/../../data/data.json'

During handling of the above exception, another exception occurred:

Traceback (most recent call last):
  File "C:\Users\Павел\PycharmProjects\homeCourse2\FLASK\lib\site-packages\flask\app.py", line 2077, in wsgi_app
    response = self.full_dispatch_request()
  File "C:\Users\Павел\PycharmProjects\homeCourse2\FLASK\lib\site-packages\flask\app.py", line 1525, in full_dispatch_request
    rv = self.handle_user_exception(e)
  File "C:\Users\Павел\PycharmProjects\homeCourse2\FLASK\lib\site-packages\flask\app.py", line 1523, in full_dispatch_request
    rv = self.dispatch_request()
  File "C:\Users\Павел\PycharmProjects\homeCourse2\FLASK\lib\site-packages\flask\app.py", line 1509, in dispatch_request
    return self.ensure_sync(self.view_functions[rule.endpoint])(**req.view_args)
  File "C:\Users\Павел\PycharmProjects\homeCourse2\app\main\views.py", line 9, in page_index
    post = posts.load_data()
  File "C:\Users\Павел\PycharmProjects\homeCourse2\app\post\dao\post_dao.py", line 21, in load_data
    raise DataSourceError(f"Не удается получить данные из файла{self.path}")
exceptions.data_exceptions.DataSourceError: Не удается получить данные из файла/../../data/data.json
INFO:werkzeug:127.0.0.1 - - [17/Jul/2022 15:32:18] "[35m[1mGET / HTTP/1.1[0m" 500 -
127.0.0.1 - - [17/Jul/2022 15:32:18] "[35m[1mGET / HTTP/1.1[0m" 500 -
INFO:werkzeug: * Running on http://127.0.0.1:5000 (Press CTRL+C to quit)
 * Running on http://127.0.0.1:5000 (Press CTRL+C to quit)
ERROR:app.run:Exception on / [GET]
Traceback (most recent call last):
  File "C:\Users\Павел\PycharmProjects\homeCourse2\app\post\dao\post_dao.py", line 18, in load_data
    with open(self.path, "r", encoding="utf-8") as f:
FileNotFoundError: [Errno 2] No such file or directory: '../../../../data/data.json'

During handling of the above exception, another exception occurred:

Traceback (most recent call last):
  File "C:\Users\Павел\PycharmProjects\homeCourse2\FLASK\lib\site-packages\flask\app.py", line 2077, in wsgi_app
    response = self.full_dispatch_request()
  File "C:\Users\Павел\PycharmProjects\homeCourse2\FLASK\lib\site-packages\flask\app.py", line 1525, in full_dispatch_request
    rv = self.handle_user_exception(e)
  File "C:\Users\Павел\PycharmProjects\homeCourse2\FLASK\lib\site-packages\flask\app.py", line 1523, in full_dispatch_request
    rv = self.dispatch_request()
  File "C:\Users\Павел\PycharmProjects\homeCourse2\FLASK\lib\site-packages\flask\app.py", line 1509, in dispatch_request
    return self.ensure_sync(self.view_functions[rule.endpoint])(**req.view_args)
  File "C:\Users\Павел\PycharmProjects\homeCourse2\app\main\views.py", line 9, in page_index
    post = posts.load_data()
  File "C:\Users\Павел\PycharmProjects\homeCourse2\app\post\dao\post_dao.py", line 21, in load_data
    raise DataSourceError(f"Не удается получить данные из файла{self.path}")
exceptions.data_exceptions.DataSourceError: Не удается получить данные из файла../../../../data/data.json
Exception on / [GET]
Traceback (most recent call last):
  File "C:\Users\Павел\PycharmProjects\homeCourse2\app\post\dao\post_dao.py", line 18, in load_data
    with open(self.path, "r", encoding="utf-8") as f:
FileNotFoundError: [Errno 2] No such file or directory: '../../../../data/data.json'

During handling of the above exception, another exception occurred:

Traceback (most recent call last):
  File "C:\Users\Павел\PycharmProjects\homeCourse2\FLASK\lib\site-packages\flask\app.py", line 2077, in wsgi_app
    response = self.full_dispatch_request()
  File "C:\Users\Павел\PycharmProjects\homeCourse2\FLASK\lib\site-packages\flask\app.py", line 1525, in full_dispatch_request
    rv = self.handle_user_exception(e)
  File "C:\Users\Павел\PycharmProjects\homeCourse2\FLASK\lib\site-packages\flask\app.py", line 1523, in full_dispatch_request
    rv = self.dispatch_request()
  File "C:\Users\Павел\PycharmProjects\homeCourse2\FLASK\lib\site-packages\flask\app.py", line 1509, in dispatch_request
    return self.ensure_sync(self.view_functions[rule.endpoint])(**req.view_args)
  File "C:\Users\Павел\PycharmProjects\homeCourse2\app\main\views.py", line 9, in page_index
    post = posts.load_data()
  File "C:\Users\Павел\PycharmProjects\homeCourse2\app\post\dao\post_dao.py", line 21, in load_data
    raise DataSourceError(f"Не удается получить данные из файла{self.path}")
exceptions.data_exceptions.DataSourceError: Не удается получить данные из файла../../../../data/data.json
INFO:werkzeug:127.0.0.1 - - [17/Jul/2022 15:32:36] "[35m[1mGET / HTTP/1.1[0m" 500 -
127.0.0.1 - - [17/Jul/2022 15:32:36] "[35m[1mGET / HTTP/1.1[0m" 500 -
INFO:werkzeug: * Running on http://127.0.0.1:5000 (Press CTRL+C to quit)
 * Running on http://127.0.0.1:5000 (Press CTRL+C to quit)
ERROR:app.run:Exception on / [GET]
Traceback (most recent call last):
  File "C:\Users\Павел\PycharmProjects\homeCourse2\app\post\dao\post_dao.py", line 18, in load_data
    with open(self.path, "r", encoding="utf-8") as f:
FileNotFoundError: [Errno 2] No such file or directory: './../../../../data/data.json'

During handling of the above exception, another exception occurred:

Traceback (most recent call last):
  File "C:\Users\Павел\PycharmProjects\homeCourse2\FLASK\lib\site-packages\flask\app.py", line 2077, in wsgi_app
    response = self.full_dispatch_request()
  File "C:\Users\Павел\PycharmProjects\homeCourse2\FLASK\lib\site-packages\flask\app.py", line 1525, in full_dispatch_request
    rv = self.handle_user_exception(e)
  File "C:\Users\Павел\PycharmProjects\homeCourse2\FLASK\lib\site-packages\flask\app.py", line 1523, in full_dispatch_request
    rv = self.dispatch_request()
  File "C:\Users\Павел\PycharmProjects\homeCourse2\FLASK\lib\site-packages\flask\app.py", line 1509, in dispatch_request
    return self.ensure_sync(self.view_functions[rule.endpoint])(**req.view_args)
  File "C:\Users\Павел\PycharmProjects\homeCourse2\app\main\views.py", line 9, in page_index
    post = posts.load_data()
  File "C:\Users\Павел\PycharmProjects\homeCourse2\app\post\dao\post_dao.py", line 21, in load_data
    raise DataSourceError(f"Не удается получить данные из файла{self.path}")
exceptions.data_exceptions.DataSourceError: Не удается получить данные из файла./../../../../data/data.json
Exception on / [GET]
Traceback (most recent call last):
  File "C:\Users\Павел\PycharmProjects\homeCourse2\app\post\dao\post_dao.py", line 18, in load_data
    with open(self.path, "r", encoding="utf-8") as f:
FileNotFoundError: [Errno 2] No such file or directory: './../../../../data/data.json'

During handling of the above exception, another exception occurred:

Traceback (most recent call last):
  File "C:\Users\Павел\PycharmProjects\homeCourse2\FLASK\lib\site-packages\flask\app.py", line 2077, in wsgi_app
    response = self.full_dispatch_request()
  File "C:\Users\Павел\PycharmProjects\homeCourse2\FLASK\lib\site-packages\flask\app.py", line 1525, in full_dispatch_request
    rv = self.handle_user_exception(e)
  File "C:\Users\Павел\PycharmProjects\homeCourse2\FLASK\lib\site-packages\flask\app.py", line 1523, in full_dispatch_request
    rv = self.dispatch_request()
  File "C:\Users\Павел\PycharmProjects\homeCourse2\FLASK\lib\site-packages\flask\app.py", line 1509, in dispatch_request
    return self.ensure_sync(self.view_functions[rule.endpoint])(**req.view_args)
  File "C:\Users\Павел\PycharmProjects\homeCourse2\app\main\views.py", line 9, in page_index
    post = posts.load_data()
  File "C:\Users\Павел\PycharmProjects\homeCourse2\app\post\dao\post_dao.py", line 21, in load_data
    raise DataSourceError(f"Не удается получить данные из файла{self.path}")
exceptions.data_exceptions.DataSourceError: Не удается получить данные из файла./../../../../data/data.json
INFO:werkzeug:127.0.0.1 - - [17/Jul/2022 15:33:09] "[35m[1mGET / HTTP/1.1[0m" 500 -
127.0.0.1 - - [17/Jul/2022 15:33:09] "[35m[1mGET / HTTP/1.1[0m" 500 -
ERROR:app.run:Exception on / [GET]
Traceback (most recent call last):
  File "C:\Users\Павел\PycharmProjects\homeCourse2\app\post\dao\post_dao.py", line 18, in load_data
    with open(self.path, "r", encoding="utf-8") as f:
FileNotFoundError: [Errno 2] No such file or directory: './../../../../data/data.json'

During handling of the above exception, another exception occurred:

Traceback (most recent call last):
  File "C:\Users\Павел\PycharmProjects\homeCourse2\FLASK\lib\site-packages\flask\app.py", line 2077, in wsgi_app
    response = self.full_dispatch_request()
  File "C:\Users\Павел\PycharmProjects\homeCourse2\FLASK\lib\site-packages\flask\app.py", line 1525, in full_dispatch_request
    rv = self.handle_user_exception(e)
  File "C:\Users\Павел\PycharmProjects\homeCourse2\FLASK\lib\site-packages\flask\app.py", line 1523, in full_dispatch_request
    rv = self.dispatch_request()
  File "C:\Users\Павел\PycharmProjects\homeCourse2\FLASK\lib\site-packages\flask\app.py", line 1509, in dispatch_request
    return self.ensure_sync(self.view_functions[rule.endpoint])(**req.view_args)
  File "C:\Users\Павел\PycharmProjects\homeCourse2\app\main\views.py", line 9, in page_index
    post = posts.load_data()
  File "C:\Users\Павел\PycharmProjects\homeCourse2\app\post\dao\post_dao.py", line 21, in load_data
    raise DataSourceError(f"Не удается получить данные из файла{self.path}")
exceptions.data_exceptions.DataSourceError: Не удается получить данные из файла./../../../../data/data.json
Exception on / [GET]
Traceback (most recent call last):
  File "C:\Users\Павел\PycharmProjects\homeCourse2\app\post\dao\post_dao.py", line 18, in load_data
    with open(self.path, "r", encoding="utf-8") as f:
FileNotFoundError: [Errno 2] No such file or directory: './../../../../data/data.json'

During handling of the above exception, another exception occurred:

Traceback (most recent call last):
  File "C:\Users\Павел\PycharmProjects\homeCourse2\FLASK\lib\site-packages\flask\app.py", line 2077, in wsgi_app
    response = self.full_dispatch_request()
  File "C:\Users\Павел\PycharmProjects\homeCourse2\FLASK\lib\site-packages\flask\app.py", line 1525, in full_dispatch_request
    rv = self.handle_user_exception(e)
  File "C:\Users\Павел\PycharmProjects\homeCourse2\FLASK\lib\site-packages\flask\app.py", line 1523, in full_dispatch_request
    rv = self.dispatch_request()
  File "C:\Users\Павел\PycharmProjects\homeCourse2\FLASK\lib\site-packages\flask\app.py", line 1509, in dispatch_request
    return self.ensure_sync(self.view_functions[rule.endpoint])(**req.view_args)
  File "C:\Users\Павел\PycharmProjects\homeCourse2\app\main\views.py", line 9, in page_index
    post = posts.load_data()
  File "C:\Users\Павел\PycharmProjects\homeCourse2\app\post\dao\post_dao.py", line 21, in load_data
    raise DataSourceError(f"Не удается получить данные из файла{self.path}")
exceptions.data_exceptions.DataSourceError: Не удается получить данные из файла./../../../../data/data.json
INFO:werkzeug:127.0.0.1 - - [17/Jul/2022 15:33:19] "[35m[1mGET / HTTP/1.1[0m" 500 -
127.0.0.1 - - [17/Jul/2022 15:33:19] "[35m[1mGET / HTTP/1.1[0m" 500 -
INFO:werkzeug: * Running on http://127.0.0.1:5000 (Press CTRL+C to quit)
 * Running on http://127.0.0.1:5000 (Press CTRL+C to quit)
ERROR:app.run:Exception on / [GET]
Traceback (most recent call last):
  File "C:\Users\Павел\PycharmProjects\homeCourse2\app\post\dao\post_dao.py", line 18, in load_data
    with open(self.path, "r", encoding="utf-8") as f:
FileNotFoundError: [Errno 2] No such file or directory: './data/data.json'

During handling of the above exception, another exception occurred:

Traceback (most recent call last):
  File "C:\Users\Павел\PycharmProjects\homeCourse2\FLASK\lib\site-packages\flask\app.py", line 2077, in wsgi_app
    response = self.full_dispatch_request()
  File "C:\Users\Павел\PycharmProjects\homeCourse2\FLASK\lib\site-packages\flask\app.py", line 1525, in full_dispatch_request
    rv = self.handle_user_exception(e)
  File "C:\Users\Павел\PycharmProjects\homeCourse2\FLASK\lib\site-packages\flask\app.py", line 1523, in full_dispatch_request
    rv = self.dispatch_request()
  File "C:\Users\Павел\PycharmProjects\homeCourse2\FLASK\lib\site-packages\flask\app.py", line 1509, in dispatch_request
    return self.ensure_sync(self.view_functions[rule.endpoint])(**req.view_args)
  File "C:\Users\Павел\PycharmProjects\homeCourse2\app\main\views.py", line 9, in page_index
    post = posts.load_data()
  File "C:\Users\Павел\PycharmProjects\homeCourse2\app\post\dao\post_dao.py", line 21, in load_data
    raise DataSourceError(f"Не удается получить данные из файла{self.path}")
exceptions.data_exceptions.DataSourceError: Не удается получить данные из файла./data/data.json
Exception on / [GET]
Traceback (most recent call last):
  File "C:\Users\Павел\PycharmProjects\homeCourse2\app\post\dao\post_dao.py", line 18, in load_data
    with open(self.path, "r", encoding="utf-8") as f:
FileNotFoundError: [Errno 2] No such file or directory: './data/data.json'

During handling of the above exception, another exception occurred:

Traceback (most recent call last):
  File "C:\Users\Павел\PycharmProjects\homeCourse2\FLASK\lib\site-packages\flask\app.py", line 2077, in wsgi_app
    response = self.full_dispatch_request()
  File "C:\Users\Павел\PycharmProjects\homeCourse2\FLASK\lib\site-packages\flask\app.py", line 1525, in full_dispatch_request
    rv = self.handle_user_exception(e)
  File "C:\Users\Павел\PycharmProjects\homeCourse2\FLASK\lib\site-packages\flask\app.py", line 1523, in full_dispatch_request
    rv = self.dispatch_request()
  File "C:\Users\Павел\PycharmProjects\homeCourse2\FLASK\lib\site-packages\flask\app.py", line 1509, in dispatch_request
    return self.ensure_sync(self.view_functions[rule.endpoint])(**req.view_args)
  File "C:\Users\Павел\PycharmProjects\homeCourse2\app\main\views.py", line 9, in page_index
    post = posts.load_data()
  File "C:\Users\Павел\PycharmProjects\homeCourse2\app\post\dao\post_dao.py", line 21, in load_data
    raise DataSourceError(f"Не удается получить данные из файла{self.path}")
exceptions.data_exceptions.DataSourceError: Не удается получить данные из файла./data/data.json
INFO:werkzeug:127.0.0.1 - - [17/Jul/2022 15:33:31] "[35m[1mGET / HTTP/1.1[0m" 500 -
127.0.0.1 - - [17/Jul/2022 15:33:31] "[35m[1mGET / HTTP/1.1[0m" 500 -
INFO:werkzeug: * Running on http://127.0.0.1:5000 (Press CTRL+C to quit)
 * Running on http://127.0.0.1:5000 (Press CTRL+C to quit)
ERROR:app.run:Exception on / [GET]
Traceback (most recent call last):
  File "C:\Users\Павел\PycharmProjects\homeCourse2\app\post\dao\post_dao.py", line 18, in load_data
    with open(self.path, "r", encoding="utf-8") as f:
FileNotFoundError: [Errno 2] No such file or directory: '../data/data.json'

During handling of the above exception, another exception occurred:

Traceback (most recent call last):
  File "C:\Users\Павел\PycharmProjects\homeCourse2\FLASK\lib\site-packages\flask\app.py", line 2077, in wsgi_app
    response = self.full_dispatch_request()
  File "C:\Users\Павел\PycharmProjects\homeCourse2\FLASK\lib\site-packages\flask\app.py", line 1525, in full_dispatch_request
    rv = self.handle_user_exception(e)
  File "C:\Users\Павел\PycharmProjects\homeCourse2\FLASK\lib\site-packages\flask\app.py", line 1523, in full_dispatch_request
    rv = self.dispatch_request()
  File "C:\Users\Павел\PycharmProjects\homeCourse2\FLASK\lib\site-packages\flask\app.py", line 1509, in dispatch_request
    return self.ensure_sync(self.view_functions[rule.endpoint])(**req.view_args)
  File "C:\Users\Павел\PycharmProjects\homeCourse2\app\main\views.py", line 9, in page_index
    post = posts.load_data()
  File "C:\Users\Павел\PycharmProjects\homeCourse2\app\post\dao\post_dao.py", line 21, in load_data
    raise DataSourceError(f"Не удается получить данные из файла{self.path}")
exceptions.data_exceptions.DataSourceError: Не удается получить данные из файла../data/data.json
Exception on / [GET]
Traceback (most recent call last):
  File "C:\Users\Павел\PycharmProjects\homeCourse2\app\post\dao\post_dao.py", line 18, in load_data
    with open(self.path, "r", encoding="utf-8") as f:
FileNotFoundError: [Errno 2] No such file or directory: '../data/data.json'

During handling of the above exception, another exception occurred:

Traceback (most recent call last):
  File "C:\Users\Павел\PycharmProjects\homeCourse2\FLASK\lib\site-packages\flask\app.py", line 2077, in wsgi_app
    response = self.full_dispatch_request()
  File "C:\Users\Павел\PycharmProjects\homeCourse2\FLASK\lib\site-packages\flask\app.py", line 1525, in full_dispatch_request
    rv = self.handle_user_exception(e)
  File "C:\Users\Павел\PycharmProjects\homeCourse2\FLASK\lib\site-packages\flask\app.py", line 1523, in full_dispatch_request
    rv = self.dispatch_request()
  File "C:\Users\Павел\PycharmProjects\homeCourse2\FLASK\lib\site-packages\flask\app.py", line 1509, in dispatch_request
    return self.ensure_sync(self.view_functions[rule.endpoint])(**req.view_args)
  File "C:\Users\Павел\PycharmProjects\homeCourse2\app\main\views.py", line 9, in page_index
    post = posts.load_data()
  File "C:\Users\Павел\PycharmProjects\homeCourse2\app\post\dao\post_dao.py", line 21, in load_data
    raise DataSourceError(f"Не удается получить данные из файла{self.path}")
exceptions.data_exceptions.DataSourceError: Не удается получить данные из файла../data/data.json
INFO:werkzeug:127.0.0.1 - - [17/Jul/2022 15:33:41] "[35m[1mGET / HTTP/1.1[0m" 500 -
127.0.0.1 - - [17/Jul/2022 15:33:41] "[35m[1mGET / HTTP/1.1[0m" 500 -
INFO:werkzeug: * Running on http://127.0.0.1:5000 (Press CTRL+C to quit)
 * Running on http://127.0.0.1:5000 (Press CTRL+C to quit)
ERROR:app.run:Exception on / [GET]
Traceback (most recent call last):
  File "C:\Users\Павел\PycharmProjects\homeCourse2\app\post\dao\post_dao.py", line 18, in load_data
    with open(self.path, "r", encoding="utf-8") as f:
FileNotFoundError: [Errno 2] No such file or directory: '/data/data.json'

During handling of the above exception, another exception occurred:

Traceback (most recent call last):
  File "C:\Users\Павел\PycharmProjects\homeCourse2\FLASK\lib\site-packages\flask\app.py", line 2077, in wsgi_app
    response = self.full_dispatch_request()
  File "C:\Users\Павел\PycharmProjects\homeCourse2\FLASK\lib\site-packages\flask\app.py", line 1525, in full_dispatch_request
    rv = self.handle_user_exception(e)
  File "C:\Users\Павел\PycharmProjects\homeCourse2\FLASK\lib\site-packages\flask\app.py", line 1523, in full_dispatch_request
    rv = self.dispatch_request()
  File "C:\Users\Павел\PycharmProjects\homeCourse2\FLASK\lib\site-packages\flask\app.py", line 1509, in dispatch_request
    return self.ensure_sync(self.view_functions[rule.endpoint])(**req.view_args)
  File "C:\Users\Павел\PycharmProjects\homeCourse2\app\main\views.py", line 9, in page_index
    post = posts.load_data()
  File "C:\Users\Павел\PycharmProjects\homeCourse2\app\post\dao\post_dao.py", line 21, in load_data
    raise DataSourceError(f"Не удается получить данные из файла{self.path}")
exceptions.data_exceptions.DataSourceError: Не удается получить данные из файла/data/data.json
Exception on / [GET]
Traceback (most recent call last):
  File "C:\Users\Павел\PycharmProjects\homeCourse2\app\post\dao\post_dao.py", line 18, in load_data
    with open(self.path, "r", encoding="utf-8") as f:
FileNotFoundError: [Errno 2] No such file or directory: '/data/data.json'

During handling of the above exception, another exception occurred:

Traceback (most recent call last):
  File "C:\Users\Павел\PycharmProjects\homeCourse2\FLASK\lib\site-packages\flask\app.py", line 2077, in wsgi_app
    response = self.full_dispatch_request()
  File "C:\Users\Павел\PycharmProjects\homeCourse2\FLASK\lib\site-packages\flask\app.py", line 1525, in full_dispatch_request
    rv = self.handle_user_exception(e)
  File "C:\Users\Павел\PycharmProjects\homeCourse2\FLASK\lib\site-packages\flask\app.py", line 1523, in full_dispatch_request
    rv = self.dispatch_request()
  File "C:\Users\Павел\PycharmProjects\homeCourse2\FLASK\lib\site-packages\flask\app.py", line 1509, in dispatch_request
    return self.ensure_sync(self.view_functions[rule.endpoint])(**req.view_args)
  File "C:\Users\Павел\PycharmProjects\homeCourse2\app\main\views.py", line 9, in page_index
    post = posts.load_data()
  File "C:\Users\Павел\PycharmProjects\homeCourse2\app\post\dao\post_dao.py", line 21, in load_data
    raise DataSourceError(f"Не удается получить данные из файла{self.path}")
exceptions.data_exceptions.DataSourceError: Не удается получить данные из файла/data/data.json
INFO:werkzeug:127.0.0.1 - - [17/Jul/2022 15:33:52] "[35m[1mGET / HTTP/1.1[0m" 500 -
127.0.0.1 - - [17/Jul/2022 15:33:52] "[35m[1mGET / HTTP/1.1[0m" 500 -
INFO:werkzeug: * Running on http://127.0.0.1:5000 (Press CTRL+C to quit)
 * Running on http://127.0.0.1:5000 (Press CTRL+C to quit)
ERROR:app.run:Exception on / [GET]
Traceback (most recent call last):
  File "C:\Users\Павел\PycharmProjects\homeCourse2\app\post\dao\post_dao.py", line 18, in load_data
    with open(self.path, "r", encoding="utf-8") as f:
FileNotFoundError: [Errno 2] No such file or directory: '/data/data.json'

During handling of the above exception, another exception occurred:

Traceback (most recent call last):
  File "C:\Users\Павел\PycharmProjects\homeCourse2\FLASK\lib\site-packages\flask\app.py", line 2077, in wsgi_app
    response = self.full_dispatch_request()
  File "C:\Users\Павел\PycharmProjects\homeCourse2\FLASK\lib\site-packages\flask\app.py", line 1525, in full_dispatch_request
    rv = self.handle_user_exception(e)
  File "C:\Users\Павел\PycharmProjects\homeCourse2\FLASK\lib\site-packages\flask\app.py", line 1523, in full_dispatch_request
    rv = self.dispatch_request()
  File "C:\Users\Павел\PycharmProjects\homeCourse2\FLASK\lib\site-packages\flask\app.py", line 1509, in dispatch_request
    return self.ensure_sync(self.view_functions[rule.endpoint])(**req.view_args)
  File "C:\Users\Павел\PycharmProjects\homeCourse2\app\main\views.py", line 9, in page_index
    post = posts.load_data()
  File "C:\Users\Павел\PycharmProjects\homeCourse2\app\post\dao\post_dao.py", line 21, in load_data
    raise DataSourceError(f"Не удается получить данные из файла{self.path}")
exceptions.data_exceptions.DataSourceError: Не удается получить данные из файла/data/data.json
Exception on / [GET]
Traceback (most recent call last):
  File "C:\Users\Павел\PycharmProjects\homeCourse2\app\post\dao\post_dao.py", line 18, in load_data
    with open(self.path, "r", encoding="utf-8") as f:
FileNotFoundError: [Errno 2] No such file or directory: '/data/data.json'

During handling of the above exception, another exception occurred:

Traceback (most recent call last):
  File "C:\Users\Павел\PycharmProjects\homeCourse2\FLASK\lib\site-packages\flask\app.py", line 2077, in wsgi_app
    response = self.full_dispatch_request()
  File "C:\Users\Павел\PycharmProjects\homeCourse2\FLASK\lib\site-packages\flask\app.py", line 1525, in full_dispatch_request
    rv = self.handle_user_exception(e)
  File "C:\Users\Павел\PycharmProjects\homeCourse2\FLASK\lib\site-packages\flask\app.py", line 1523, in full_dispatch_request
    rv = self.dispatch_request()
  File "C:\Users\Павел\PycharmProjects\homeCourse2\FLASK\lib\site-packages\flask\app.py", line 1509, in dispatch_request
    return self.ensure_sync(self.view_functions[rule.endpoint])(**req.view_args)
  File "C:\Users\Павел\PycharmProjects\homeCourse2\app\main\views.py", line 9, in page_index
    post = posts.load_data()
  File "C:\Users\Павел\PycharmProjects\homeCourse2\app\post\dao\post_dao.py", line 21, in load_data
    raise DataSourceError(f"Не удается получить данные из файла{self.path}")
exceptions.data_exceptions.DataSourceError: Не удается получить данные из файла/data/data.json
INFO:werkzeug:127.0.0.1 - - [17/Jul/2022 15:34:21] "[35m[1mGET / HTTP/1.1[0m" 500 -
127.0.0.1 - - [17/Jul/2022 15:34:21] "[35m[1mGET / HTTP/1.1[0m" 500 -
INFO:werkzeug: * Running on http://127.0.0.1:5000 (Press CTRL+C to quit)
 * Running on http://127.0.0.1:5000 (Press CTRL+C to quit)
INFO:werkzeug:127.0.0.1 - - [18/Jul/2022 10:04:46] "GET /users/leo HTTP/1.1" 200 -
127.0.0.1 - - [18/Jul/2022 10:04:46] "GET /users/leo HTTP/1.1" 200 -
INFO:werkzeug:127.0.0.1 - - [18/Jul/2022 10:04:46] "[36mGET /static/styles.min.css HTTP/1.1[0m" 304 -
127.0.0.1 - - [18/Jul/2022 10:04:46] "[36mGET /static/styles.min.css HTTP/1.1[0m" 304 -
INFO:werkzeug:127.0.0.1 - - [18/Jul/2022 10:04:48] "GET / HTTP/1.1" 200 -
127.0.0.1 - - [18/Jul/2022 10:04:48] "GET / HTTP/1.1" 200 -
INFO:werkzeug:127.0.0.1 - - [18/Jul/2022 10:04:48] "[36mGET /static/styles.min.css HTTP/1.1[0m" 304 -
127.0.0.1 - - [18/Jul/2022 10:04:48] "[36mGET /static/styles.min.css HTTP/1.1[0m" 304 -
INFO:werkzeug:127.0.0.1 - - [18/Jul/2022 10:04:50] "GET /search HTTP/1.1" 200 -
127.0.0.1 - - [18/Jul/2022 10:04:50] "GET /search HTTP/1.1" 200 -
INFO:werkzeug:127.0.0.1 - - [18/Jul/2022 10:04:50] "[36mGET /static/styles.min.css HTTP/1.1[0m" 304 -
127.0.0.1 - - [18/Jul/2022 10:04:50] "[36mGET /static/styles.min.css HTTP/1.1[0m" 304 -
INFO:werkzeug:127.0.0.1 - - [18/Jul/2022 10:04:51] "GET / HTTP/1.1" 200 -
127.0.0.1 - - [18/Jul/2022 10:04:51] "GET / HTTP/1.1" 200 -
INFO:werkzeug:127.0.0.1 - - [18/Jul/2022 10:04:51] "[36mGET /static/styles.min.css HTTP/1.1[0m" 304 -
127.0.0.1 - - [18/Jul/2022 10:04:51] "[36mGET /static/styles.min.css HTTP/1.1[0m" 304 -
INFO:werkzeug:127.0.0.1 - - [18/Jul/2022 10:04:53] "GET /search HTTP/1.1" 200 -
127.0.0.1 - - [18/Jul/2022 10:04:53] "GET /search HTTP/1.1" 200 -
INFO:werkzeug:127.0.0.1 - - [18/Jul/2022 10:04:53] "[36mGET /static/styles.min.css HTTP/1.1[0m" 304 -
127.0.0.1 - - [18/Jul/2022 10:04:53] "[36mGET /static/styles.min.css HTTP/1.1[0m" 304 -
INFO:werkzeug:127.0.0.1 - - [18/Jul/2022 10:04:56] "GET /search?s=еда HTTP/1.1" 200 -
127.0.0.1 - - [18/Jul/2022 10:04:56] "GET /search?s=еда HTTP/1.1" 200 -
INFO:werkzeug:127.0.0.1 - - [18/Jul/2022 10:04:56] "[36mGET /static/styles.min.css HTTP/1.1[0m" 304 -
127.0.0.1 - - [18/Jul/2022 10:04:56] "[36mGET /static/styles.min.css HTTP/1.1[0m" 304 -
